Workbook

Sheet 자사매출추정표
B2: 2025년도 매출처별 매출 현황
E3: (단위: 백만원)
B4: 구분 | C4: 매출처 | D4: 매출액 | E4: 경쟁사명
B5: 1
B6: 2
B7: 3
B8: 4
B9: 5
D10: =SUM(D5:D9) -> 0
B12: 향후 1년후 목표 매출액
E13: (단위: 백만원)
B14: 구분 | C14: 매출처 | D14: 매출액 | E14: 경쟁사명
B15: 1
B16: 2
B17: 3
B18: 4
B19: 5
B20: 목표매출액 | D20: =SUM(D15:D19) -> 0

Sheet AS-IS스펙표
B4: (AS-IS) 스펙표
B6: 핵심스펙(기능) | C6: 세부스펙(기능) | D6: 기술적 특성

Sheet 제품속성표
B2: 제품속성서
B3: 제품명 | C3: 고객명 | D3: 세분시장 | E3: 고객 니즈 | F3: 제공혜택 | G3: 제품속성 | H3: 기술 역량

Sheet 제품속성적합도
B2: 제품 속성 적합도
B4: 속성 | C4: 시장 A | E4: 시장 B | G4: 시장 C
C5: 세분화1 | D5: 세분화2 | E5: 세분화1 | F5: 세분화2 | G5: 세분화1 | H5: 세분화2
B6: 속성1
B7: 속성2
B8: 속성3
B9: 속성4
B10: 속성5
B11: 속성6
B12: 속성7
B13: 속성8
B14: 속성9
B15: 속성10
B16: 우선순위 | C16: =RANK(C17,$C$17:$H$17) -> 1 | D16: =RANK(D17,$C$17:$H$17) -> 1 | E16: =RANK(E17,$C$17:$H$17) -> 1 | F16: =RANK(F17,$C$17:$H$17) -> 1 | G16: =RANK(G17,$C$17:$H$17) -> 1 | H16: =RANK(H17,$C$17:$H$17) -> 1
B17: H | C17: =COUNTIF(C$6:C$15,$B17) -> 0 | D17: =COUNTIF(D$6:D$15,$B17) -> 0 | E17: =COUNTIF(E$6:E$15,$B17) -> 0 | F17: =COUNTIF(F$6:F$15,$B17) -> 0 | G17: =COUNTIF(G$6:G$15,$B17) -> 0 | H17: =COUNTIF(H$6:H$15,$B17) -> 0
B18: M | C18: =COUNTIF(C$6:C$15,$B18) -> 0 | D18: =COUNTIF(D$6:D$15,$B18) -> 0 | E18: =COUNTIF(E$6:E$15,$B18) -> 0 | F18: =COUNTIF(F$6:F$15,$B18) -> 0 | G18: =COUNTIF(G$6:G$15,$B18) -> 0 | H18: =COUNTIF(H$6:H$15,$B18) -> 0
B19: L | C19: =COUNTIF(C$6:C$15,$B19) -> 0 | D19: =COUNTIF(D$6:D$15,$B19) -> 0 | E19: =COUNTIF(E$6:E$15,$B19) -> 0 | F19: =COUNTIF(F$6:F$15,$B19) -> 0 | G19: =COUNTIF(G$6:G$15,$B19) -> 0 | H19: =COUNTIF(H$6:H$15,$B19) -> 0
B20: L* | C20: =COUNTIF(C$6:C$15,$B20) -> 0 | D20: =COUNTIF(D$6:D$15,$B20) -> 0 | E20: =COUNTIF(E$6:E$15,$B20) -> 0 | F20: =COUNTIF(F$6:F$15,$B20) -> 0 | G20: =COUNTIF(G$6:G$15,$B20) -> 0 | H20: =COUNTIF(H$6:H$15,$B20) -> 0

Sheet 고객요구사항도출표
B2: 고객요구사항 도출표
B4: 번호 | C4: 항목(검정색 글씨) | D4: 1차 그룹(빨간색 글씨) | E4: 2차 그룹(파란색 글씨)
B5: 1
B6: 2
B7: 3
B8: 4
B9: 5
B10: 6
B11: 7
B12: 8
B13: 9
B14: 10
B15: 11
B16: 12
... B39: 35
B41: 제품컨셉
B44: 제품명

Sheet KANO질문지
E1: 1 | Q1: 2 | AC1: 3 | AO1: 4 | BA1: 5 | BM1: 6 | BZ1: 7 | CL1: 8 | CX1: 9 | DJ1: 10 | DV1: 11 | EH1: 12 | ET1: 13 | FF1: 14 | FR1: 15 | GD1: 16 | GQ1: 17 | HC1: 18 | HO1: 19 | IA1: 20
E2: (1)마음에 든다 | F2: (2)당연하다 | G2: (3)아무런 느낌이 없다 | H2: (4)하는수 없다. | I2: (5)마음에 안든다 | J2: 매력적 | K2: 일원적 | L2: 당연적 | M2: 역(逆) | N2: 무관심 | O2: 회의적 | Q2: (1)마음에 든다 | R2: (2)당연하다 | S2: (3)아무런 느낌이 없다 | T2: (4)하는수 없다. | U2: (5)마음에 안든다 | V2: 매력적 | W2: 일원적 | X2: 당연적 | Y2: 역(逆) | Z2: 무관심 | AA2: 회의적 | AC2: (1)마음에 든다 | AD2: (2)당연하다 | AE2: (3)아무런 느낌이 없다 | AF2: (4)하는수 없다. | AG2: (5)마음에 안든다 | AH2: 매력적 | AI2: 일원적 | AJ2: 당연적 | AK2: 역(逆) | AL2: 무관심 | AM2: 회의적 | AO2: (1)마음에 든다 | AP2: (2)당연하다 | AQ2: (3)아무런 느낌이 없다 | AR2: (4)하는수 없다. | AS2: (5)마음에 안든다 | AT2: 매력적 | AU2: 일원적 | AV2: 당연적 | AW2: 역(逆) | AX2: 무관심 | AY2: 회의적 | BA2: (1)마음에 든다 | BB2: (2)당연하다 | BC2: (3)아무런 느낌이 없다 | BD2: (4)하는수 없다. | BE2: (5)마음에 안든다 | BF2: 매력적 | BG2: 일원적 | BH2: 당연적 | BI2: 역(逆) | BJ2: 무관심 | BK2: 회의적 | BM2: (1)마음에 든다 | BN2: (2)당연하다 | BO2: (3)아무런 느낌이 없다 | BP2: (4)하는수 없다. | BQ2: (5)마음에 안든다 | BR2: (6)기타 | BS2: 매력적 | BT2: 일원적 | BU2: 당연적 | BV2: 역(逆) | BW2: 무관심 | BX2: 회의적 | BZ2: (1)마음에 든다 | CA2: (2)당연하다 | CB2: (3)아무런 느낌이 없다 | CC2: (4)하는수 없다. | CD2: (5)마음에 안든다 | CE2: 매력적 | CF2: 일원적 | CG2: 당연적 | CH2: 역(逆) | CI2: 무관심 | CJ2: 회의적 | CL2: (1)마음에 든다 | CM2: (2)당연하다 | CN2: (3)아무런 느낌이 없다 | CO2: (4)하는수 없다. | CP2: (5)마음에 안든다 | CQ2: 매력적 | CR2: 일원적 | CS2: 당연적 | CT2: 역(逆) | CU2: 무관심 | CV2: 회의적 | CX2: (1)마음에 든다 | CY2: (2)당연하다 | CZ2: (3)아무런 느낌이 없다 | DA2: (4)하는수 없다. | DB2: (5)마음에 안든다 | DC2: 매력적 | DD2: 일원적 | DE2: 당연적 | DF2: 역(逆) | DG2: 무관심 | DH2: 회의적 | DJ2: (1)마음에 든다 | DK2: (2)당연하다 | DL2: (3)아무런 느낌이 없다 | DM2: (4)하는수 없다. | DN2: (5)마음에 안든다 | DO2: 매력적 | DP2: 일원적 | DQ2: 당연적 | DR2: 역(逆) | DS2: 무관심 | DT2: 회의적 | DV2: (1)마음에 든다 | DW2: (2)당연하다 | DX2: (3)아무런 느낌이 없다 | DY2: (4)하는수 없다. | DZ2: (5)마음에 안든다 | EA2: 매력적 | EB2: 일원적 | EC2: 당연적 | ED2: 역(逆) | EE2: 무관심 | EF2: 회의적 | EH2: (1)마음에 든다 | EI2: (2)당연하다 | EJ2: (3)아무런 느낌이 없다 | EK2: (4)하는수 없다. | EL2: (5)마음에 안든다 | EM2: 매력적 | EN2: 일원적 | EO2: 당연적 | EP2: 역(逆) | EQ2: 무관심 | ER2: 회의적 | ET2: (1)마음에 든다 | EU2: (2)당연하다 | EV2: (3)아무런 느낌이 없다 | EW2: (4)하는수 없다. | EX2: (5)마음에 안든다 | EY2: 매력적 | EZ2: 일원적 | FA2: 당연적 | FB2: 역(逆) | FC2: 무관심 | FD2: 회의적 | FF2: (1)마음에 든다 | FG2: (2)당연하다 | FH2: (3)아무런 느낌이 없다 | FI2: (4)하는수 없다. | FJ2: (5)마음에 안든다 | FK2: 매력적 | FL2: 일원적 | FM2: 당연적 | FN2: 역(逆) | FO2: 무관심 | FP2: 회의적 | FR2: (1)마음에 든다 | FS2: (2)당연하다 | FT2: (3)아무런 느낌이 없다 | FU2: (4)하는수 없다. | FV2: (5)마음에 안든다 | FW2: 매력적 | FX2: 일원적 | FY2: 당연적 | FZ2: 역(逆) | GA2: 무관심 | GB2: 회의적 | GD2: (1)마음에 든다 | GE2: (2)당연하다 | GF2: (3)아무런 느낌이 없다 | GG2: (4)하는수 없다. | GH2: (5)마음에 안든다 | GI2: (6)기타 | GJ2: 매력적 | GK2: 일원적 | GL2: 당연적 | GM2: 역(逆) | GN2: 무관심 | GO2: 회의적 | GQ2: (1)마음에 든다 | GR2: (2)당연하다 | GS2: (3)아무런 느낌이 없다 | GT2: (4)하는수 없다. | GU2: (5)마음에 안든다 | GV2: 매력적 | GW2: 일원적 | GX2: 당연적 | GY2: 역(逆) | GZ2: 무관심 | HA2: 회의적 | HC2: (1)마음에 든다 | HD2: (2)당연하다 | HE2: (3)아무런 느낌이 없다 | HF2: (4)하는수 없다. | HG2: (5)마음에 안든다 | HH2: 매력적 | HI2: 일원적 | HJ2: 당연적 | HK2: 역(逆) | HL2: 무관심 | HM2: 회의적 | HO2: (1)마음에 든다 | HP2: (2)당연하다 | HQ2: (3)아무런 느낌이 없다 | HR2: (4)하는수 없다. | HS2: (5)마음에 안든다 | HT2: 매력적 | HU2: 일원적 | HV2: 당연적 | HW2: 역(逆) | HX2: 무관심 | HY2: 회의적 | IA2: (1)마음에 든다 | IB2: (2)당연하다 | IC2: (3)아무런 느낌이 없다 | ID2: (4)하는수 없다. | IE2: (5)마음에 안든다 | IF2: 매력적 | IG2: 일원적 | IH2: 당연적 | II2: 역(逆) | IJ2: 무관심 | IK2: 회의적 | IL2: 매력적 | IM2: 일원적 | IN2: 당연적 | IO2: 역(逆) | IP2: 무관심 | IQ2: 회의적
B3: 1 | C3: =고객요구사항도출표!C5 -> 0 | D3: 긍정적 질문 | J3: =IF(AND(E3="*",OR(F4="*",G4="*",H4="*")), 1,"") | K3: =IF(AND(E3="*",I4="*"),1,"") | L3: =IF(AND(I4="*", OR(F3="*", G3="*",H3="*")),1,"") | M3: =IF(AND(E4="*",OR(F3="*",G3="*",H3="*",I3="*")),1,IF(AND(I3="*",OR(E4="*",F4="*",G4="*",H4="*")),1,"")) | N3: =IF(AND(F3="*",OR(F4="*",G4="*",H4="*")),1,IF(AND(G3="*",OR(F4="*",G4="*",H4="*")),1,IF(AND(H3="*",OR(F4="*",G4="*",H4="*")),1,""))) | O3: =IF(AND(E3="*",E4="*"),1,"") | V3: =IF(AND(Q3="*",OR(R4="*",S4="*",T4="*")), 1,"") | W3: =IF(AND(Q3="*",U4="*"),1,"") | X3: =IF(AND(U4="*", OR(R3="*", S3="*",T3="*")),1,"") | Y3: =IF(AND(Q4="*",OR(R3="*",S3="*",T3="*",U3="*")),1,IF(AND(U3="*",OR(Q4="*",R4="*",S4="*",T4="*")),1,"")) | Z3: =IF(AND(R3="*",OR(R4="*",S4="*",T4="*")),1,IF(AND(S3="*",OR(R4="*",S4="*",T4="*")),1,IF(AND(T3="*",OR(R4="*",S4="*",T4="*")),1,""))) | AA3: =IF(AND(Q3="*",Q4="*"),1,"") | AH3: =IF(AND(AC3="*",OR(AD4="*",AE4="*",AF4="*")), 1,"") | AI3: =IF(AND(AC3="*",AG4="*"),1,"") | AJ3: =IF(AND(AG4="*", OR(AD3="*", AE3="*",AF3="*")),1,"") | AK3: =IF(AND(AC4="*",OR(AD3="*",AE3="*",AF3="*",AG3="*")),1,IF(AND(AG3="*",OR(AC4="*",AD4="*",AE4="*",AF4="*")),1,"")) | AL3: =IF(AND(AD3="*",OR(AD4="*",AE4="*",AF4="*")),1,IF(AND(AE3="*",OR(AD4="*",AE4="*",AF4="*")),1,IF(AND(AF3="*",OR(AD4="*",AE4="*",AF4="*")),1,""))) | AM3: =IF(AND(AC3="*",AC4="*"),1,"") | AT3: =IF(AND(AO3="*",OR(AP4="*",AQ4="*",AR4="*")), 1,"") | AU3: =IF(AND(AO3="*",AS4="*"),1,"") | AV3: =IF(AND(AS4="*", OR(AP3="*", AQ3="*",AR3="*")),1,"") | AW3: =IF(AND(AO4="*",OR(AP3="*",AQ3="*",AR3="*",AS3="*")),1,IF(AND(AS3="*",OR(AO4="*",AP4="*",AQ4="*",AR4="*")),1,"")) | AX3: =IF(AND(AP3="*",OR(AP4="*",AQ4="*",AR4="*")),1,IF(AND(AQ3="*",OR(AP4="*",AQ4="*",AR4="*")),1,IF(AND(AR3="*",OR(AP4="*",AQ4="*",AR4="*")),1,""))) | AY3: =IF(AND(AO3="*",AO4="*"),1,"") | BF3: =IF(AND(BA3="*",OR(BB4="*",BC4="*",BD4="*")), 1,"") | BG3: =IF(AND(BA3="*",BE4="*"),1,"") | BH3: =IF(AND(BE4="*", OR(BB3="*", BC3="*",BD3="*")),1,"") | BI3: =IF(AND(BA4="*",OR(BB3="*",BC3="*",BD3="*",BE3="*")),1,IF(AND(BE3="*",OR(BA4="*",BB4="*",BC4="*",BD4="*")),1,"")) | BJ3: =IF(AND(BB3="*",OR(BB4="*",BC4="*",BD4="*")),1,IF(AND(BC3="*",OR(BB4="*",BC4="*",BD4="*")),1,IF(AND(BD3="*",OR(BB4="*",BC4="*",BD4="*")),1,""))) | BK3: =IF(AND(BA3="*",BA4="*"),1,"") | BS3: =IF(AND(BM3="*",OR(BN4="*",BO4="*",BP4="*")), 1,"") | BT3: =IF(AND(BM3="*",BQ4="*"),1,"") | BU3: =IF(AND(BQ4="*", OR(BN3="*", BO3="*",BP3="*")),1,"") | BV3: =IF(AND(BM4="*",OR(BN3="*",BO3="*",BP3="*",BQ3="*")),1,IF(AND(BQ3="*",OR(BM4="*",BN4="*",BO4="*",BP4="*")),1,"")) | BW3: =IF(AND(BN3="*",OR(BN4="*",BO4="*",BP4="*")),1,IF(AND(BO3="*",OR(BN4="*",BO4="*",BP4="*")),1,IF(AND(BP3="*",OR(BN4="*",BO4="*",BP4="*")),1,""))) | BX3: =IF(AND(BM3="*",BM4="*"),1,"") | CE3: =IF(AND(BZ3="*",OR(CA4="*",CB4="*",CC4="*")), 1,"") | CF3: =IF(AND(BZ3="*",CD4="*"),1,"") | CG3: =IF(AND(CD4="*", OR(CA3="*", CB3="*",CC3="*")),1,"") | CH3: =IF(AND(BZ4="*",OR(CA3="*",CB3="*",CC3="*",CD3="*")),1,IF(AND(CD3="*",OR(BZ4="*",CA4="*",CB4="*",CC4="*")),1,"")) | CI3: =IF(AND(CA3="*",OR(CA4="*",CB4="*",CC4="*")),1,IF(AND(CB3="*",OR(CA4="*",CB4="*",CC4="*")),1,IF(AND(CC3="*",OR(CA4="*",CB4="*",CC4="*")),1,""))) | CJ3: =IF(AND(BZ3="*",BZ4="*"),1,"") | CQ3: =IF(AND(CL3="*",OR(CM4="*",CN4="*",CO4="*")), 1,"") | CR3: =IF(AND(CL3="*",CP4="*"),1,"") | CS3: =IF(AND(CP4="*", OR(CM3="*", CN3="*",CO3="*")),1,"") | CT3: =IF(AND(CL4="*",OR(CM3="*",CN3="*",CO3="*",CP3="*")),1,IF(AND(CP3="*",OR(CL4="*",CM4="*",CN4="*",CO4="*")),1,"")) | CU3: =IF(AND(CM3="*",OR(CM4="*",CN4="*",CO4="*")),1,IF(AND(CN3="*",OR(CM4="*",CN4="*",CO4="*")),1,IF(AND(CO3="*",OR(CM4="*",CN4="*",CO4="*")),1,""))) | CV3: =IF(AND(CL3="*",CL4="*"),1,"") | DC3: =IF(AND(CX3="*",OR(CY4="*",CZ4="*",DA4="*")), 1,"") | DD3: =IF(AND(CX3="*",DB4="*"),1,"") | DE3: =IF(AND(DB4="*", OR(CY3="*", CZ3="*",DA3="*")),1,"") | DF3: =IF(AND(CX4="*",OR(CY3="*",CZ3="*",DA3="*",DB3="*")),1,IF(AND(DB3="*",OR(CX4="*",CY4="*",CZ4="*",DA4="*")),1,"")) | DG3: =IF(AND(CY3="*",OR(CY4="*",CZ4="*",DA4="*")),1,IF(AND(CZ3="*",OR(CY4="*",CZ4="*",DA4="*")),1,IF(AND(DA3="*",OR(CY4="*",CZ4="*",DA4="*")),1,""))) | DH3: =IF(AND(CX3="*",CX4="*"),1,"") | DO3: =IF(AND(DJ3="*",OR(DK4="*",DL4="*",DM4="*")), 1,"") | DP3: =IF(AND(DJ3="*",DN4="*"),1,"") | DQ3: =IF(AND(DN4="*", OR(DK3="*", DL3="*",DM3="*")),1,"") | DR3: =IF(AND(DJ4="*",OR(DK3="*",DL3="*",DM3="*",DN3="*")),1,IF(AND(DN3="*",OR(DJ4="*",DK4="*",DL4="*",DM4="*")),1,"")) | DS3: =IF(AND(DK3="*",OR(DK4="*",DL4="*",DM4="*")),1,IF(AND(DL3="*",OR(DK4="*",DL4="*",DM4="*")),1,IF(AND(DM3="*",OR(DK4="*",DL4="*",DM4="*")),1,""))) | DT3: =IF(AND(DJ3="*",DJ4="*"),1,"") | EA3: =IF(AND(DV3="*",OR(DW4="*",DX4="*",DY4="*")), 1,"") | EB3: =IF(AND(DV3="*",DZ4="*"),1,"") | EC3: =IF(AND(DZ4="*", OR(DW3="*", DX3="*",DY3="*")),1,"") | ED3: =IF(AND(DV4="*",OR(DW3="*",DX3="*",DY3="*",DZ3="*")),1,IF(AND(DZ3="*",OR(DV4="*",DW4="*",DX4="*",DY4="*")),1,"")) | EE3: =IF(AND(DW3="*",OR(DW4="*",DX4="*",DY4="*")),1,IF(AND(DX3="*",OR(DW4="*",DX4="*",DY4="*")),1,IF(AND(DY3="*",OR(DW4="*",DX4="*",DY4="*")),1,""))) | EF3: =IF(AND(DV3="*",DV4="*"),1,"") | EM3: =IF(AND(EH3="*",OR(EI4="*",EJ4="*",EK4="*")), 1,"") | EN3: =IF(AND(EH3="*",EL4="*"),1,"") | EO3: =IF(AND(EL4="*", OR(EI3="*", EJ3="*",EK3="*")),1,"") | EP3: =IF(AND(EH4="*",OR(EI3="*",EJ3="*",EK3="*",EL3="*")),1,IF(AND(EL3="*",OR(EH4="*",EI4="*",EJ4="*",EK4="*")),1,"")) | EQ3: =IF(AND(EI3="*",OR(EI4="*",EJ4="*",EK4="*")),1,IF(AND(EJ3="*",OR(EI4="*",EJ4="*",EK4="*")),1,IF(AND(EK3="*",OR(EI4="*",EJ4="*",EK4="*")),1,""))) | ER3: =IF(AND(EH3="*",EH4="*"),1,"") | EY3: =IF(AND(ET3="*",OR(EU4="*",EV4="*",EW4="*")), 1,"") | EZ3: =IF(AND(ET3="*",EX4="*"),1,"") | FA3: =IF(AND(EX4="*", OR(EU3="*", EV3="*",EW3="*")),1,"") | FB3: =IF(AND(ET4="*",OR(EU3="*",EV3="*",EW3="*",EX3="*")),1,IF(AND(EX3="*",OR(ET4="*",EU4="*",EV4="*",EW4="*")),1,"")) | FC3: =IF(AND(EU3="*",OR(EU4="*",EV4="*",EW4="*")),1,IF(AND(EV3="*",OR(EU4="*",EV4="*",EW4="*")),1,IF(AND(EW3="*",OR(EU4="*",EV4="*",EW4="*")),1,""))) | FD3: =IF(AND(ET3="*",ET4="*"),1,"") | FK3: =IF(AND(FF3="*",OR(FG4="*",FH4="*",FI4="*")), 1,"") | FL3: =IF(AND(FF3="*",FJ4="*"),1,"") | FM3: =IF(AND(FJ4="*", OR(FG3="*", FH3="*",FI3="*")),1,"") | FN3: =IF(AND(FF4="*",OR(FG3="*",FH3="*",FI3="*",FJ3="*")),1,IF(AND(FJ3="*",OR(FF4="*",FG4="*",FH4="*",FI4="*")),1,"")) | FO3: =IF(AND(FG3="*",OR(FG4="*",FH4="*",FI4="*")),1,IF(AND(FH3="*",OR(FG4="*",FH4="*",FI4="*")),1,IF(AND(FI3="*",OR(FG4="*",FH4="*",FI4="*")),1,""))) | FP3: =IF(AND(FF3="*",FF4="*"),1,"") | FW3: =IF(AND(FR3="*",OR(FS4="*",FT4="*",FU4="*")), 1,"") | FX3: =IF(AND(FR3="*",FV4="*"),1,"") | FY3: =IF(AND(FV4="*", OR(FS3="*", FT3="*",FU3="*")),1,"") | FZ3: =IF(AND(FR4="*",OR(FS3="*",FT3="*",FU3="*",FV3="*")),1,IF(AND(FV3="*",OR(FR4="*",FS4="*",FT4="*",FU4="*")),1,"")) | GA3: =IF(AND(FS3="*",OR(FS4="*",FT4="*",FU4="*")),1,IF(AND(FT3="*",OR(FS4="*",FT4="*",FU4="*")),1,IF(AND(FU3="*",OR(FS4="*",FT4="*",FU4="*")),1,""))) | GB3: =IF(AND(FR3="*",FR4="*"),1,"") | GJ3: =IF(AND(GD3="*",OR(GE4="*",GF4="*",GG4="*")), 1,"") | GK3: =IF(AND(GD3="*",GH4="*"),1,"") | GL3: =IF(AND(GH4="*", OR(GE3="*", GF3="*",GG3="*")),1,"") | GM3: =IF(AND(GD4="*",OR(GE3="*",GF3="*",GG3="*",GH3="*")),1,IF(AND(GH3="*",OR(GD4="*",GE4="*",GF4="*",GG4="*")),1,"")) | GN3: =IF(AND(GE3="*",OR(GE4="*",GF4="*",GG4="*")),1,IF(AND(GF3="*",OR(GE4="*",GF4="*",GG4="*")),1,IF(AND(GG3="*",OR(GE4="*",GF4="*",GG4="*")),1,""))) | GO3: =IF(AND(GD3="*",GD4="*"),1,"") | GV3: =IF(AND(GQ3="*",OR(GR4="*",GS4="*",GT4="*")), 1,"") | GW3: =IF(AND(GQ3="*",GU4="*"),1,"") | GX3: =IF(AND(GU4="*", OR(GR3="*", GS3="*",GT3="*")),1,"") | GY3: =IF(AND(GQ4="*",OR(GR3="*",GS3="*",GT3="*",GU3="*")),1,IF(AND(GU3="*",OR(GQ4="*",GR4="*",GS4="*",GT4="*")),1,"")) | GZ3: =IF(AND(GR3="*",OR(GR4="*",GS4="*",GT4="*")),1,IF(AND(GS3="*",OR(GR4="*",GS4="*",GT4="*")),1,IF(AND(GT3="*",OR(GR4="*",GS4="*",GT4="*")),1,""))) | HA3: =IF(AND(GQ3="*",GQ4="*"),1,"") | HH3: =IF(AND(HC3="*",OR(HD4="*",HE4="*",HF4="*")), 1,"") | HI3: =IF(AND(HC3="*",HG4="*"),1,"") | HJ3: =IF(AND(HG4="*", OR(HD3="*", HE3="*",HF3="*")),1,"") | HK3: =IF(AND(HC4="*",OR(HD3="*",HE3="*",HF3="*",HG3="*")),1,IF(AND(HG3="*",OR(HC4="*",HD4="*",HE4="*",HF4="*")),1,"")) | HL3: =IF(AND(HD3="*",OR(HD4="*",HE4="*",HF4="*")),1,IF(AND(HE3="*",OR(HD4="*",HE4="*",HF4="*")),1,IF(AND(HF3="*",OR(HD4="*",HE4="*",HF4="*")),1,""))) | HM3: =IF(AND(HC3="*",HC4="*"),1,"") | HT3: =IF(AND(HO3="*",OR(HP4="*",HQ4="*",HR4="*")), 1,"") | HU3: =IF(AND(HO3="*",HS4="*"),1,"") | HV3: =IF(AND(HS4="*", OR(HP3="*", HQ3="*",HR3="*")),1,"") | HW3: =IF(AND(HO4="*",OR(HP3="*",HQ3="*",HR3="*",HS3="*")),1,IF(AND(HS3="*",OR(HO4="*",HP4="*",HQ4="*",HR4="*")),1,"")) | HX3: =IF(AND(HP3="*",OR(HP4="*",HQ4="*",HR4="*")),1,IF(AND(HQ3="*",OR(HP4="*",HQ4="*",HR4="*")),1,IF(AND(HR3="*",OR(HP4="*",HQ4="*",HR4="*")),1,""))) | HY3: =IF(AND(HO3="*",HO4="*"),1,"") | IF3: =IF(AND(IA3="*",OR(IB4="*",IC4="*",ID4="*")), 1,"") | IG3: =IF(AND(IA3="*",IE4="*"),1,"") | IH3: =IF(AND(IE4="*", OR(IB3="*", IC3="*",ID3="*")),1,"") | II3: =IF(AND(IA4="*",OR(IB3="*",IC3="*",ID3="*",IE3="*")),1,IF(AND(IE3="*",OR(IA4="*",IB4="*",IC4="*",ID4="*")),1,"")) | IJ3: =IF(AND(IB3="*",OR(IB4="*",IC4="*",ID4="*")),1,IF(AND(IC3="*",OR(IB4="*",IC4="*",ID4="*")),1,IF(AND(ID3="*",OR(IB4="*",IC4="*",ID4="*")),1,""))) | IK3: =IF(AND(IA3="*",IA4="*"),1,"") | IL3: =COUNT(J3,V3,AH3,AT3,BF3,BS3,CE3,CQ3,DC3,DO3,EA3,EM3,EY3,FK3,FW3,GJ3,GV3,HH3,HT3,IF3) -> 0 | IM3: =COUNT(K3,W3,AI3,AU3,BG3,BT3,CF3,CR3,DD3,DP3,EB3,EN3,EZ3,FL3,FX3,GK3,GW3,HI3,HU3,IG3) -> 0 | IN3: =COUNT(L3,X3,AJ3,AV3,BH3,BU3,CG3,CS3,DE3,DQ3,EC3,EO3,FA3,FM3,FY3,GL3,GX3,HJ3,HV3,IH3) -> 0 | IO3: =COUNT(M3,Y3,AK3,AW3,BI3,BV3,CH3,CT3,DF3,DR3,ED3,EP3,FB3,FN3,FZ3,GM3,GY3,HK3,HW3,II3) -> 0 | IP3: =COUNT(N3,Z3,AL3,AX3,BJ3,BW3,CI3,CU3,DG3,DS3,EE3,EQ3,FC3,FO3,GA3,GN3,GZ3,HL3,HX3,IJ3) -> 0 | IQ3: =COUNT(O3,AA3,AM3,AY3,BK3,BX3,CJ3,CV3,DH3,DT3,EF3,ER3,FD3,FP3,GB3,GO3,HA3,HM3,HY3,IK3) -> 0
D4: 부정적 질문
B5: 2 | C5: =고객요구사항도출표!C6 -> 0 | D5: 긍정적 질문 | J5: =IF(AND(E5="*",OR(F6="*",G6="*",H6="*")), 1,"") | K5: =IF(AND(E5="*",I6="*"),1,"") | L5: =IF(AND(I6="*", OR(F5="*", G5="*",H5="*")),1,"") | M5: =IF(AND(E6="*",OR(F5="*",G5="*",H5="*",I5="*")),1,IF(AND(I5="*",OR(E6="*",F6="*",G6="*",H6="*")),1,"")) | N5: =IF(AND(F5="*",OR(F6="*",G6="*",H6="*")),1,IF(AND(G5="*",OR(F6="*",G6="*",H6="*")),1,IF(AND(H5="*",OR(F6="*",G6="*",H6="*")),1,""))) | O5: =IF(AND(E5="*",E6="*"),1,"") | V5: =IF(AND(Q5="*",OR(R6="*",S6="*",T6="*")), 1,"") | W5: =IF(AND(Q5="*",U6="*"),1,"") | X5: =IF(AND(U6="*", OR(R5="*", S5="*",T5="*")),1,"") | Y5: =IF(AND(Q6="*",OR(R5="*",S5="*",T5="*",U5="*")),1,IF(AND(U5="*",OR(Q6="*",R6="*",S6="*",T6="*")),1,"")) | Z5: =IF(AND(R5="*",OR(R6="*",S6="*",T6="*")),1,IF(AND(S5="*",OR(R6="*",S6="*",T6="*")),1,IF(AND(T5="*",OR(R6="*",S6="*",T6="*")),1,""))) | AA5: =IF(AND(Q5="*",Q6="*"),1,"") | AH5: =IF(AND(AC5="*",OR(AD6="*",AE6="*",AF6="*")), 1,"") | AI5: =IF(AND(AC5="*",AG6="*"),1,"") | AJ5: =IF(AND(AG6="*", OR(AD5="*", AE5="*",AF5="*")),1,"") | AK5: =IF(AND(AC6="*",OR(AD5="*",AE5="*",AF5="*",AG5="*")),1,IF(AND(AG5="*",OR(AC6="*",AD6="*",AE6="*",AF6="*")),1,"")) | AL5: =IF(AND(AD5="*",OR(AD6="*",AE6="*",AF6="*")),1,IF(AND(AE5="*",OR(AD6="*",AE6="*",AF6="*")),1,IF(AND(AF5="*",OR(AD6="*",AE6="*",AF6="*")),1,""))) | AM5: =IF(AND(AC5="*",AC6="*"),1,"") | AT5: =IF(AND(AO5="*",OR(AP6="*",AQ6="*",AR6="*")), 1,"") | AU5: =IF(AND(AO5="*",AS6="*"),1,"") | AV5: =IF(AND(AS6="*", OR(AP5="*", AQ5="*",AR5="*")),1,"") | AW5: =IF(AND(AO6="*",OR(AP5="*",AQ5="*",AR5="*",AS5="*")),1,IF(AND(AS5="*",OR(AO6="*",AP6="*",AQ6="*",AR6="*")),1,"")) | AX5: =IF(AND(AP5="*",OR(AP6="*",AQ6="*",AR6="*")),1,IF(AND(AQ5="*",OR(AP6="*",AQ6="*",AR6="*")),1,IF(AND(AR5="*",OR(AP6="*",AQ6="*",AR6="*")),1,""))) | AY5: =IF(AND(AO5="*",AO6="*"),1,"") | BF5: =IF(AND(BA5="*",OR(BB6="*",BC6="*",BD6="*")), 1,"") | BG5: =IF(AND(BA5="*",BE6="*"),1,"") | BH5: =IF(AND(BE6="*", OR(BB5="*", BC5="*",BD5="*")),1,"") | BI5: =IF(AND(BA6="*",OR(BB5="*",BC5="*",BD5="*",BE5="*")),1,IF(AND(BE5="*",OR(BA6="*",BB6="*",BC6="*",BD6="*")),1,"")) | BJ5: =IF(AND(BB5="*",OR(BB6="*",BC6="*",BD6="*")),1,IF(AND(BC5="*",OR(BB6="*",BC6="*",BD6="*")),1,IF(AND(BD5="*",OR(BB6="*",BC6="*",BD6="*")),1,""))) | BK5: =IF(AND(BA5="*",BA6="*"),1,"") | BS5: =IF(AND(BM5="*",OR(BN6="*",BO6="*",BP6="*")), 1,"") | BT5: =IF(AND(BM5="*",BQ6="*"),1,"") | BU5: =IF(AND(BQ6="*", OR(BN5="*", BO5="*",BP5="*")),1,"") | BV5: =IF(AND(BM6="*",OR(BN5="*",BO5="*",BP5="*",BQ5="*")),1,IF(AND(BQ5="*",OR(BM6="*",BN6="*",BO6="*",BP6="*")),1,"")) | BW5: =IF(AND(BN5="*",OR(BN6="*",BO6="*",BP6="*")),1,IF(AND(BO5="*",OR(BN6="*",BO6="*",BP6="*")),1,IF(AND(BP5="*",OR(BN6="*",BO6="*",BP6="*")),1,""))) | BX5: =IF(AND(BM5="*",BM6="*"),1,"") | CE5: =IF(AND(BZ5="*",OR(CA6="*",CB6="*",CC6="*")), 1,"") | CF5: =IF(AND(BZ5="*",CD6="*"),1,"") | CG5: =IF(AND(CD6="*", OR(CA5="*", CB5="*",CC5="*")),1,"") | CH5: =IF(AND(BZ6="*",OR(CA5="*",CB5="*",CC5="*",CD5="*")),1,IF(AND(CD5="*",OR(BZ6="*",CA6="*",CB6="*",CC6="*")),1,"")) | CI5: =IF(AND(CA5="*",OR(CA6="*",CB6="*",CC6="*")),1,IF(AND(CB5="*",OR(CA6="*",CB6="*",CC6="*")),1,IF(AND(CC5="*",OR(CA6="*",CB6="*",CC6="*")),1,""))) | CJ5: =IF(AND(BZ5="*",BZ6="*"),1,"") | CQ5: =IF(AND(CL5="*",OR(CM6="*",CN6="*",CO6="*")), 1,"") | CR5: =IF(AND(CL5="*",CP6="*"),1,"") | CS5: =IF(AND(CP6="*", OR(CM5="*", CN5="*",CO5="*")),1,"") | CT5: =IF(AND(CL6="*",OR(CM5="*",CN5="*",CO5="*",CP5="*")),1,IF(AND(CP5="*",OR(CL6="*",CM6="*",CN6="*",CO6="*")),1,"")) | CU5: =IF(AND(CM5="*",OR(CM6="*",CN6="*",CO6="*")),1,IF(AND(CN5="*",OR(CM6="*",CN6="*",CO6="*")),1,IF(AND(CO5="*",OR(CM6="*",CN6="*",CO6="*")),1,""))) | CV5: =IF(AND(CL5="*",CL6="*"),1,"") | DC5: =IF(AND(CX5="*",OR(CY6="*",CZ6="*",DA6="*")), 1,"") | DD5: =IF(AND(CX5="*",DB6="*"),1,"") | DE5: =IF(AND(DB6="*", OR(CY5="*", CZ5="*",DA5="*")),1,"") | DF5: =IF(AND(CX6="*",OR(CY5="*",CZ5="*",DA5="*",DB5="*")),1,IF(AND(DB5="*",OR(CX6="*",CY6="*",CZ6="*",DA6="*")),1,"")) | DG5: =IF(AND(CY5="*",OR(CY6="*",CZ6="*",DA6="*")),1,IF(AND(CZ5="*",OR(CY6="*",CZ6="*",DA6="*")),1,IF(AND(DA5="*",OR(CY6="*",CZ6="*",DA6="*")),1,""))) | DH5: =IF(AND(CX5="*",CX6="*"),1,"") | DO5: =IF(AND(DJ5="*",OR(DK6="*",DL6="*",DM6="*")), 1,"") | DP5: =IF(AND(DJ5="*",DN6="*"),1,"") | DQ5: =IF(AND(DN6="*", OR(DK5="*", DL5="*",DM5="*")),1,"") | DR5: =IF(AND(DJ6="*",OR(DK5="*",DL5="*",DM5="*",DN5="*")),1,IF(AND(DN5="*",OR(DJ6="*",DK6="*",DL6="*",DM6="*")),1,"")) | DS5: =IF(AND(DK5="*",OR(DK6="*",DL6="*",DM6="*")),1,IF(AND(DL5="*",OR(DK6="*",DL6="*",DM6="*")),1,IF(AND(DM5="*",OR(DK6="*",DL6="*",DM6="*")),1,""))) | DT5: =IF(AND(DJ5="*",DJ6="*"),1,"") | EA5: =IF(AND(DV5="*",OR(DW6="*",DX6="*",DY6="*")), 1,"") | EB5: =IF(AND(DV5="*",DZ6="*"),1,"") | EC5: =IF(AND(DZ6="*", OR(DW5="*", DX5="*",DY5="*")),1,"") | ED5: =IF(AND(DV6="*",OR(DW5="*",DX5="*",DY5="*",DZ5="*")),1,IF(AND(DZ5="*",OR(DV6="*",DW6="*",DX6="*",DY6="*")),1,"")) | EE5: =IF(AND(DW5="*",OR(DW6="*",DX6="*",DY6="*")),1,IF(AND(DX5="*",OR(DW6="*",DX6="*",DY6="*")),1,IF(AND(DY5="*",OR(DW6="*",DX6="*",DY6="*")),1,""))) | EF5: =IF(AND(DV5="*",DV6="*"),1,"") | EM5: =IF(AND(EH5="*",OR(EI6="*",EJ6="*",EK6="*")), 1,"") | EN5: =IF(AND(EH5="*",EL6="*"),1,"") | EO5: =IF(AND(EL6="*", OR(EI5="*", EJ5="*",EK5="*")),1,"") | EP5: =IF(AND(EH6="*",OR(EI5="*",EJ5="*",EK5="*",EL5="*")),1,IF(AND(EL5="*",OR(EH6="*",EI6="*",EJ6="*",EK6="*")),1,"")) | EQ5: =IF(AND(EI5="*",OR(EI6="*",EJ6="*",EK6="*")),1,IF(AND(EJ5="*",OR(EI6="*",EJ6="*",EK6="*")),1,IF(AND(EK5="*",OR(EI6="*",EJ6="*",EK6="*")),1,""))) | ER5: =IF(AND(EH5="*",EH6="*"),1,"") | EY5: =IF(AND(ET5="*",OR(EU6="*",EV6="*",EW6="*")), 1,"") | EZ5: =IF(AND(ET5="*",EX6="*"),1,"") | FA5: =IF(AND(EX6="*", OR(EU5="*", EV5="*",EW5="*")),1,"") | FB5: =IF(AND(ET6="*",OR(EU5="*",EV5="*",EW5="*",EX5="*")),1,IF(AND(EX5="*",OR(ET6="*",EU6="*",EV6="*",EW6="*")),1,"")) | FC5: =IF(AND(EU5="*",OR(EU6="*",EV6="*",EW6="*")),1,IF(AND(EV5="*",OR(EU6="*",EV6="*",EW6="*")),1,IF(AND(EW5="*",OR(EU6="*",EV6="*",EW6="*")),1,""))) | FD5: =IF(AND(ET5="*",ET6="*"),1,"") | FK5: =IF(AND(FF5="*",OR(FG6="*",FH6="*",FI6="*")), 1,"") | FL5: =IF(AND(FF5="*",FJ6="*"),1,"") | FM5: =IF(AND(FJ6="*", OR(FG5="*", FH5="*",FI5="*")),1,"") | FN5: =IF(AND(FF6="*",OR(FG5="*",FH5="*",FI5="*",FJ5="*")),1,IF(AND(FJ5="*",OR(FF6="*",FG6="*",FH6="*",FI6="*")),1,"")) | FO5: =IF(AND(FG5="*",OR(FG6="*",FH6="*",FI6="*")),1,IF(AND(FH5="*",OR(FG6="*",FH6="*",FI6="*")),1,IF(AND(FI5="*",OR(FG6="*",FH6="*",FI6="*")),1,""))) | FP5: =IF(AND(FF5="*",FF6="*"),1,"") | FW5: =IF(AND(FR5="*",OR(FS6="*",FT6="*",FU6="*")), 1,"") | FX5: =IF(AND(FR5="*",FV6="*"),1,"") | FY5: =IF(AND(FV6="*", OR(FS5="*", FT5="*",FU5="*")),1,"") | FZ5: =IF(AND(FR6="*",OR(FS5="*",FT5="*",FU5="*",FV5="*")),1,IF(AND(FV5="*",OR(FR6="*",FS6="*",FT6="*",FU6="*")),1,"")) | GA5: =IF(AND(FS5="*",OR(FS6="*",FT6="*",FU6="*")),1,IF(AND(FT5="*",OR(FS6="*",FT6="*",FU6="*")),1,IF(AND(FU5="*",OR(FS6="*",FT6="*",FU6="*")),1,""))) | GB5: =IF(AND(FR5="*",FR6="*"),1,"") | GJ5: =IF(AND(GD5="*",OR(GE6="*",GF6="*",GG6="*")), 1,"") | GK5: =IF(AND(GD5="*",GH6="*"),1,"") | GL5: =IF(AND(GH6="*", OR(GE5="*", GF5="*",GG5="*")),1,"") | GM5: =IF(AND(GD6="*",OR(GE5="*",GF5="*",GG5="*",GH5="*")),1,IF(AND(GH5="*",OR(GD6="*",GE6="*",GF6="*",GG6="*")),1,"")) | GN5: =IF(AND(GE5="*",OR(GE6="*",GF6="*",GG6="*")),1,IF(AND(GF5="*",OR(GE6="*",GF6="*",GG6="*")),1,IF(AND(GG5="*",OR(GE6="*",GF6="*",GG6="*")),1,""))) | GO5: =IF(AND(GD5="*",GD6="*"),1,"") | GV5: =IF(AND(GQ5="*",OR(GR6="*",GS6="*",GT6="*")), 1,"") | GW5: =IF(AND(GQ5="*",GU6="*"),1,"") | GX5: =IF(AND(GU6="*", OR(GR5="*", GS5="*",GT5="*")),1,"") | GY5: =IF(AND(GQ6="*",OR(GR5="*",GS5="*",GT5="*",GU5="*")),1,IF(AND(GU5="*",OR(GQ6="*",GR6="*",GS6="*",GT6="*")),1,"")) | GZ5: =IF(AND(GR5="*",OR(GR6="*",GS6="*",GT6="*")),1,IF(AND(GS5="*",OR(GR6="*",GS6="*",GT6="*")),1,IF(AND(GT5="*",OR(GR6="*",GS6="*",GT6="*")),1,""))) | HA5: =IF(AND(GQ5="*",GQ6="*"),1,"") | HH5: =IF(AND(HC5="*",OR(HD6="*",HE6="*",HF6="*")), 1,"") | HI5: =IF(AND(HC5="*",HG6="*"),1,"") | HJ5: =IF(AND(HG6="*", OR(HD5="*", HE5="*",HF5="*")),1,"") | HK5: =IF(AND(HC6="*",OR(HD5="*",HE5="*",HF5="*",HG5="*")),1,IF(AND(HG5="*",OR(HC6="*",HD6="*",HE6="*",HF6="*")),1,"")) | HL5: =IF(AND(HD5="*",OR(HD6="*",HE6="*",HF6="*")),1,IF(AND(HE5="*",OR(HD6="*",HE6="*",HF6="*")),1,IF(AND(HF5="*",OR(HD6="*",HE6="*",HF6="*")),1,""))) | HM5: =IF(AND(HC5="*",HC6="*"),1,"") | HT5: =IF(AND(HO5="*",OR(HP6="*",HQ6="*",HR6="*")), 1,"") | HU5: =IF(AND(HO5="*",HS6="*"),1,"") | HV5: =IF(AND(HS6="*", OR(HP5="*", HQ5="*",HR5="*")),1,"") | HW5: =IF(AND(HO6="*",OR(HP5="*",HQ5="*",HR5="*",HS5="*")),1,IF(AND(HS5="*",OR(HO6="*",HP6="*",HQ6="*",HR6="*")),1,"")) | HX5: =IF(AND(HP5="*",OR(HP6="*",HQ6="*",HR6="*")),1,IF(AND(HQ5="*",OR(HP6="*",HQ6="*",HR6="*")),1,IF(AND(HR5="*",OR(HP6="*",HQ6="*",HR6="*")),1,""))) | HY5: =IF(AND(HO5="*",HO6="*"),1,"") | IF5: =IF(AND(IA5="*",OR(IB6="*",IC6="*",ID6="*")), 1,"") | IG5: =IF(AND(IA5="*",IE6="*"),1,"") | IH5: =IF(AND(IE6="*", OR(IB5="*", IC5="*",ID5="*")),1,"") | II5: =IF(AND(IA6="*",OR(IB5="*",IC5="*",ID5="*",IE5="*")),1,IF(AND(IE5="*",OR(IA6="*",IB6="*",IC6="*",ID6="*")),1,"")) | IJ5: =IF(AND(IB5="*",OR(IB6="*",IC6="*",ID6="*")),1,IF(AND(IC5="*",OR(IB6="*",IC6="*",ID6="*")),1,IF(AND(ID5="*",OR(IB6="*",IC6="*",ID6="*")),1,""))) | IK5: =IF(AND(IA5="*",IA6="*"),1,"") | IL5: =COUNT(J5,V5,AH5,AT5,BF5,BS5,CE5,CQ5,DC5,DO5,EA5,EM5,EY5,FK5,FW5,GJ5,GV5,HH5,HT5,IF5) -> 0 | IM5: =COUNT(K5,W5,AI5,AU5,BG5,BT5,CF5,CR5,DD5,DP5,EB5,EN5,EZ5,FL5,FX5,GK5,GW5,HI5,HU5,IG5) -> 0 | IN5: =COUNT(L5,X5,AJ5,AV5,BH5,BU5,CG5,CS5,DE5,DQ5,EC5,EO5,FA5,FM5,FY5,GL5,GX5,HJ5,HV5,IH5) -> 0 | IO5: =COUNT(M5,Y5,AK5,AW5,BI5,BV5,CH5,CT5,DF5,DR5,ED5,EP5,FB5,FN5,FZ5,GM5,GY5,HK5,HW5,II5) -> 0 | IP5: =COUNT(N5,Z5,AL5,AX5,BJ5,BW5,CI5,CU5,DG5,DS5,EE5,EQ5,FC5,FO5,GA5,GN5,GZ5,HL5,HX5,IJ5) -> 0 | IQ5: =COUNT(O5,AA5,AM5,AY5,BK5,BX5,CJ5,CV5,DH5,DT5,EF5,ER5,FD5,FP5,GB5,GO5,HA5,HM5,HY5,IK5) -> 0
D6: 부정적 질문
B7: 3 | C7: =고객요구사항도출표!C7 -> 0 | D7: 긍정적 질문 | J7: =IF(AND(E7="*",OR(F8="*",G8="*",H8="*")), 1,"") | K7: =IF(AND(E7="*",I8="*"),1,"") | L7: =IF(AND(I8="*", OR(F7="*", G7="*",H7="*")),1,"") | M7: =IF(AND(E8="*",OR(F7="*",G7="*",H7="*",I7="*")),1,IF(AND(I7="*",OR(E8="*",F8="*",G8="*",H8="*")),1,"")) | N7: =IF(AND(F7="*",OR(F8="*",G8="*",H8="*")),1,IF(AND(G7="*",OR(F8="*",G8="*",H8="*")),1,IF(AND(H7="*",OR(F8="*",G8="*",H8="*")),1,""))) | O7: =IF(AND(E7="*",E8="*"),1,"") | V7: =IF(AND(Q7="*",OR(R8="*",S8="*",T8="*")), 1,"") | W7: =IF(AND(Q7="*",U8="*"),1,"") | X7: =IF(AND(U8="*", OR(R7="*", S7="*",T7="*")),1,"") | Y7: =IF(AND(Q8="*",OR(R7="*",S7="*",T7="*",U7="*")),1,IF(AND(U7="*",OR(Q8="*",R8="*",S8="*",T8="*")),1,"")) | Z7: =IF(AND(R7="*",OR(R8="*",S8="*",T8="*")),1,IF(AND(S7="*",OR(R8="*",S8="*",T8="*")),1,IF(AND(T7="*",OR(R8="*",S8="*",T8="*")),1,""))) | AA7: =IF(AND(Q7="*",Q8="*"),1,"") | AH7: =IF(AND(AC7="*",OR(AD8="*",AE8="*",AF8="*")), 1,"") | AI7: =IF(AND(AC7="*",AG8="*"),1,"") | AJ7: =IF(AND(AG8="*", OR(AD7="*", AE7="*",AF7="*")),1,"") | AK7: =IF(AND(AC8="*",OR(AD7="*",AE7="*",AF7="*",AG7="*")),1,IF(AND(AG7="*",OR(AC8="*",AD8="*",AE8="*",AF8="*")),1,"")) | AL7: =IF(AND(AD7="*",OR(AD8="*",AE8="*",AF8="*")),1,IF(AND(AE7="*",OR(AD8="*",AE8="*",AF8="*")),1,IF(AND(AF7="*",OR(AD8="*",AE8="*",AF8="*")),1,""))) | AM7: =IF(AND(AC7="*",AC8="*"),1,"") | AT7: =IF(AND(AO7="*",OR(AP8="*",AQ8="*",AR8="*")), 1,"") | AU7: =IF(AND(AO7="*",AS8="*"),1,"") | AV7: =IF(AND(AS8="*", OR(AP7="*", AQ7="*",AR7="*")),1,"") | AW7: =IF(AND(AO8="*",OR(AP7="*",AQ7="*",AR7="*",AS7="*")),1,IF(AND(AS7="*",OR(AO8="*",AP8="*",AQ8="*",AR8="*")),1,"")) | AX7: =IF(AND(AP7="*",OR(AP8="*",AQ8="*",AR8="*")),1,IF(AND(AQ7="*",OR(AP8="*",AQ8="*",AR8="*")),1,IF(AND(AR7="*",OR(AP8="*",AQ8="*",AR8="*")),1,""))) | AY7: =IF(AND(AO7="*",AO8="*"),1,"") | BF7: =IF(AND(BA7="*",OR(BB8="*",BC8="*",BD8="*")), 1,"") | BG7: =IF(AND(BA7="*",BE8="*"),1,"") | BH7: =IF(AND(BE8="*", OR(BB7="*", BC7="*",BD7="*")),1,"") | BI7: =IF(AND(BA8="*",OR(BB7="*",BC7="*",BD7="*",BE7="*")),1,IF(AND(BE7="*",OR(BA8="*",BB8="*",BC8="*",BD8="*")),1,"")) | BJ7: =IF(AND(BB7="*",OR(BB8="*",BC8="*",BD8="*")),1,IF(AND(BC7="*",OR(BB8="*",BC8="*",BD8="*")),1,IF(AND(BD7="*",OR(BB8="*",BC8="*",BD8="*")),1,""))) | BK7: =IF(AND(BA7="*",BA8="*"),1,"") | BS7: =IF(AND(BM7="*",OR(BN8="*",BO8="*",BP8="*")), 1,"") | BT7: =IF(AND(BM7="*",BQ8="*"),1,"") | BU7: =IF(AND(BQ8="*", OR(BN7="*", BO7="*",BP7="*")),1,"") | BV7: =IF(AND(BM8="*",OR(BN7="*",BO7="*",BP7="*",BQ7="*")),1,IF(AND(BQ7="*",OR(BM8="*",BN8="*",BO8="*",BP8="*")),1,"")) | BW7: =IF(AND(BN7="*",OR(BN8="*",BO8="*",BP8="*")),1,IF(AND(BO7="*",OR(BN8="*",BO8="*",BP8="*")),1,IF(AND(BP7="*",OR(BN8="*",BO8="*",BP8="*")),1,""))) | BX7: =IF(AND(BM7="*",BM8="*"),1,"") | CE7: =IF(AND(BZ7="*",OR(CA8="*",CB8="*",CC8="*")), 1,"") | CF7: =IF(AND(BZ7="*",CD8="*"),1,"") | CG7: =IF(AND(CD8="*", OR(CA7="*", CB7="*",CC7="*")),1,"") | CH7: =IF(AND(BZ8="*",OR(CA7="*",CB7="*",CC7="*",CD7="*")),1,IF(AND(CD7="*",OR(BZ8="*",CA8="*",CB8="*",CC8="*")),1,"")) | CI7: =IF(AND(CA7="*",OR(CA8="*",CB8="*",CC8="*")),1,IF(AND(CB7="*",OR(CA8="*",CB8="*",CC8="*")),1,IF(AND(CC7="*",OR(CA8="*",CB8="*",CC8="*")),1,""))) | CJ7: =IF(AND(BZ7="*",BZ8="*"),1,"") | CQ7: =IF(AND(CL7="*",OR(CM8="*",CN8="*",CO8="*")), 1,"") | CR7: =IF(AND(CL7="*",CP8="*"),1,"") | CS7: =IF(AND(CP8="*", OR(CM7="*", CN7="*",CO7="*")),1,"") | CT7: =IF(AND(CL8="*",OR(CM7="*",CN7="*",CO7="*",CP7="*")),1,IF(AND(CP7="*",OR(CL8="*",CM8="*",CN8="*",CO8="*")),1,"")) | CU7: =IF(AND(CM7="*",OR(CM8="*",CN8="*",CO8="*")),1,IF(AND(CN7="*",OR(CM8="*",CN8="*",CO8="*")),1,IF(AND(CO7="*",OR(CM8="*",CN8="*",CO8="*")),1,""))) | CV7: =IF(AND(CL7="*",CL8="*"),1,"") | DC7: =IF(AND(CX7="*",OR(CY8="*",CZ8="*",DA8="*")), 1,"") | DD7: =IF(AND(CX7="*",DB8="*"),1,"") | DE7: =IF(AND(DB8="*", OR(CY7="*", CZ7="*",DA7="*")),1,"") | DF7: =IF(AND(CX8="*",OR(CY7="*",CZ7="*",DA7="*",DB7="*")),1,IF(AND(DB7="*",OR(CX8="*",CY8="*",CZ8="*",DA8="*")),1,"")) | DG7: =IF(AND(CY7="*",OR(CY8="*",CZ8="*",DA8="*")),1,IF(AND(CZ7="*",OR(CY8="*",CZ8="*",DA8="*")),1,IF(AND(DA7="*",OR(CY8="*",CZ8="*",DA8="*")),1,""))) | DH7: =IF(AND(CX7="*",CX8="*"),1,"") | DO7: =IF(AND(DJ7="*",OR(DK8="*",DL8="*",DM8="*")), 1,"") | DP7: =IF(AND(DJ7="*",DN8="*"),1,"") | DQ7: =IF(AND(DN8="*", OR(DK7="*", DL7="*",DM7="*")),1,"") | DR7: =IF(AND(DJ8="*",OR(DK7="*",DL7="*",DM7="*",DN7="*")),1,IF(AND(DN7="*",OR(DJ8="*",DK8="*",DL8="*",DM8="*")),1,"")) | DS7: =IF(AND(DK7="*",OR(DK8="*",DL8="*",DM8="*")),1,IF(AND(DL7="*",OR(DK8="*",DL8="*",DM8="*")),1,IF(AND(DM7="*",OR(DK8="*",DL8="*",DM8="*")),1,""))) | DT7: =IF(AND(DJ7="*",DJ8="*"),1,"") | EA7: =IF(AND(DV7="*",OR(DW8="*",DX8="*",DY8="*")), 1,"") | EB7: =IF(AND(DV7="*",DZ8="*"),1,"") | EC7: =IF(AND(DZ8="*", OR(DW7="*", DX7="*",DY7="*")),1,"") | ED7: =IF(AND(DV8="*",OR(DW7="*",DX7="*",DY7="*",DZ7="*")),1,IF(AND(DZ7="*",OR(DV8="*",DW8="*",DX8="*",DY8="*")),1,"")) | EE7: =IF(AND(DW7="*",OR(DW8="*",DX8="*",DY8="*")),1,IF(AND(DX7="*",OR(DW8="*",DX8="*",DY8="*")),1,IF(AND(DY7="*",OR(DW8="*",DX8="*",DY8="*")),1,""))) | EF7: =IF(AND(DV7="*",DV8="*"),1,"") | EM7: =IF(AND(EH7="*",OR(EI8="*",EJ8="*",EK8="*")), 1,"") | EN7: =IF(AND(EH7="*",EL8="*"),1,"") | EO7: =IF(AND(EL8="*", OR(EI7="*", EJ7="*",EK7="*")),1,"") | EP7: =IF(AND(EH8="*",OR(EI7="*",EJ7="*",EK7="*",EL7="*")),1,IF(AND(EL7="*",OR(EH8="*",EI8="*",EJ8="*",EK8="*")),1,"")) | EQ7: =IF(AND(EI7="*",OR(EI8="*",EJ8="*",EK8="*")),1,IF(AND(EJ7="*",OR(EI8="*",EJ8="*",EK8="*")),1,IF(AND(EK7="*",OR(EI8="*",EJ8="*",EK8="*")),1,""))) | ER7: =IF(AND(EH7="*",EH8="*"),1,"") | EY7: =IF(AND(ET7="*",OR(EU8="*",EV8="*",EW8="*")), 1,"") | EZ7: =IF(AND(ET7="*",EX8="*"),1,"") | FA7: =IF(AND(EX8="*", OR(EU7="*", EV7="*",EW7="*")),1,"") | FB7: =IF(AND(ET8="*",OR(EU7="*",EV7="*",EW7="*",EX7="*")),1,IF(AND(EX7="*",OR(ET8="*",EU8="*",EV8="*",EW8="*")),1,"")) | FC7: =IF(AND(EU7="*",OR(EU8="*",EV8="*",EW8="*")),1,IF(AND(EV7="*",OR(EU8="*",EV8="*",EW8="*")),1,IF(AND(EW7="*",OR(EU8="*",EV8="*",EW8="*")),1,""))) | FD7: =IF(AND(ET7="*",ET8="*"),1,"") | FK7: =IF(AND(FF7="*",OR(FG8="*",FH8="*",FI8="*")), 1,"") | FL7: =IF(AND(FF7="*",FJ8="*"),1,"") | FM7: =IF(AND(FJ8="*", OR(FG7="*", FH7="*",FI7="*")),1,"") | FN7: =IF(AND(FF8="*",OR(FG7="*",FH7="*",FI7="*",FJ7="*")),1,IF(AND(FJ7="*",OR(FF8="*",FG8="*",FH8="*",FI8="*")),1,"")) | FO7: =IF(AND(FG7="*",OR(FG8="*",FH8="*",FI8="*")),1,IF(AND(FH7="*",OR(FG8="*",FH8="*",FI8="*")),1,IF(AND(FI7="*",OR(FG8="*",FH8="*",FI8="*")),1,""))) | FP7: =IF(AND(FF7="*",FF8="*"),1,"") | FW7: =IF(AND(FR7="*",OR(FS8="*",FT8="*",FU8="*")), 1,"") | FX7: =IF(AND(FR7="*",FV8="*"),1,"") | FY7: =IF(AND(FV8="*", OR(FS7="*", FT7="*",FU7="*")),1,"") | FZ7: =IF(AND(FR8="*",OR(FS7="*",FT7="*",FU7="*",FV7="*")),1,IF(AND(FV7="*",OR(FR8="*",FS8="*",FT8="*",FU8="*")),1,"")) | GA7: =IF(AND(FS7="*",OR(FS8="*",FT8="*",FU8="*")),1,IF(AND(FT7="*",OR(FS8="*",FT8="*",FU8="*")),1,IF(AND(FU7="*",OR(FS8="*",FT8="*",FU8="*")),1,""))) | GB7: =IF(AND(FR7="*",FR8="*"),1,"") | GJ7: =IF(AND(GD7="*",OR(GE8="*",GF8="*",GG8="*")), 1,"") | GK7: =IF(AND(GD7="*",GH8="*"),1,"") | GL7: =IF(AND(GH8="*", OR(GE7="*", GF7="*",GG7="*")),1,"") | GM7: =IF(AND(GD8="*",OR(GE7="*",GF7="*",GG7="*",GH7="*")),1,IF(AND(GH7="*",OR(GD8="*",GE8="*",GF8="*",GG8="*")),1,"")) | GN7: =IF(AND(GE7="*",OR(GE8="*",GF8="*",GG8="*")),1,IF(AND(GF7="*",OR(GE8="*",GF8="*",GG8="*")),1,IF(AND(GG7="*",OR(GE8="*",GF8="*",GG8="*")),1,""))) | GO7: =IF(AND(GD7="*",GD8="*"),1,"") | GV7: =IF(AND(GQ7="*",OR(GR8="*",GS8="*",GT8="*")), 1,"") | GW7: =IF(AND(GQ7="*",GU8="*"),1,"") | GX7: =IF(AND(GU8="*", OR(GR7="*", GS7="*",GT7="*")),1,"") | GY7: =IF(AND(GQ8="*",OR(GR7="*",GS7="*",GT7="*",GU7="*")),1,IF(AND(GU7="*",OR(GQ8="*",GR8="*",GS8="*",GT8="*")),1,"")) | GZ7: =IF(AND(GR7="*",OR(GR8="*",GS8="*",GT8="*")),1,IF(AND(GS7="*",OR(GR8="*",GS8="*",GT8="*")),1,IF(AND(GT7="*",OR(GR8="*",GS8="*",GT8="*")),1,""))) | HA7: =IF(AND(GQ7="*",GQ8="*"),1,"") | HH7: =IF(AND(HC7="*",OR(HD8="*",HE8="*",HF8="*")), 1,"") | HI7: =IF(AND(HC7="*",HG8="*"),1,"") | HJ7: =IF(AND(HG8="*", OR(HD7="*", HE7="*",HF7="*")),1,"") | HK7: =IF(AND(HC8="*",OR(HD7="*",HE7="*",HF7="*",HG7="*")),1,IF(AND(HG7="*",OR(HC8="*",HD8="*",HE8="*",HF8="*")),1,"")) | HL7: =IF(AND(HD7="*",OR(HD8="*",HE8="*",HF8="*")),1,IF(AND(HE7="*",OR(HD8="*",HE8="*",HF8="*")),1,IF(AND(HF7="*",OR(HD8="*",HE8="*",HF8="*")),1,""))) | HM7: =IF(AND(HC7="*",HC8="*"),1,"") | HT7: =IF(AND(HO7="*",OR(HP8="*",HQ8="*",HR8="*")), 1,"") | HU7: =IF(AND(HO7="*",HS8="*"),1,"") | HV7: =IF(AND(HS8="*", OR(HP7="*", HQ7="*",HR7="*")),1,"") | HW7: =IF(AND(HO8="*",OR(HP7="*",HQ7="*",HR7="*",HS7="*")),1,IF(AND(HS7="*",OR(HO8="*",HP8="*",HQ8="*",HR8="*")),1,"")) | HX7: =IF(AND(HP7="*",OR(HP8="*",HQ8="*",HR8="*")),1,IF(AND(HQ7="*",OR(HP8="*",HQ8="*",HR8="*")),1,IF(AND(HR7="*",OR(HP8="*",HQ8="*",HR8="*")),1,""))) | HY7: =IF(AND(HO7="*",HO8="*"),1,"") | IF7: =IF(AND(IA7="*",OR(IB8="*",IC8="*",ID8="*")), 1,"") | IG7: =IF(AND(IA7="*",IE8="*"),1,"") | IH7: =IF(AND(IE8="*", OR(IB7="*", IC7="*",ID7="*")),1,"") | II7: =IF(AND(IA8="*",OR(IB7="*",IC7="*",ID7="*",IE7="*")),1,IF(AND(IE7="*",OR(IA8="*",IB8="*",IC8="*",ID8="*")),1,"")) | IJ7: =IF(AND(IB7="*",OR(IB8="*",IC8="*",ID8="*")),1,IF(AND(IC7="*",OR(IB8="*",IC8="*",ID8="*")),1,IF(AND(ID7="*",OR(IB8="*",IC8="*",ID8="*")),1,""))) | IK7: =IF(AND(IA7="*",IA8="*"),1,"") | IL7: =COUNT(J7,V7,AH7,AT7,BF7,BS7,CE7,CQ7,DC7,DO7,EA7,EM7,EY7,FK7,FW7,GJ7,GV7,HH7,HT7,IF7) -> 0 | IM7: =COUNT(K7,W7,AI7,AU7,BG7,BT7,CF7,CR7,DD7,DP7,EB7,EN7,EZ7,FL7,FX7,GK7,GW7,HI7,HU7,IG7) -> 0 | IN7: =COUNT(L7,X7,AJ7,AV7,BH7,BU7,CG7,CS7,DE7,DQ7,EC7,EO7,FA7,FM7,FY7,GL7,GX7,HJ7,HV7,IH7) -> 0 | IO7: =COUNT(M7,Y7,AK7,AW7,BI7,BV7,CH7,CT7,DF7,DR7,ED7,EP7,FB7,FN7,FZ7,GM7,GY7,HK7,HW7,II7) -> 0 | IP7: =COUNT(N7,Z7,AL7,AX7,BJ7,BW7,CI7,CU7,DG7,DS7,EE7,EQ7,FC7,FO7,GA7,GN7,GZ7,HL7,HX7,IJ7) -> 0 | IQ7: =COUNT(O7,AA7,AM7,AY7,BK7,BX7,CJ7,CV7,DH7,DT7,EF7,ER7,FD7,FP7,GB7,GO7,HA7,HM7,HY7,IK7) -> 0
D8: 부정적 질문
B9: 4 | C9: =고객요구사항도출표!C8 -> 0 | D9: 긍정적 질문 | J9: =IF(AND(E9="*",OR(F10="*",G10="*",H10="*")), 1,"") | K9: =IF(AND(E9="*",I10="*"),1,"") | L9: =IF(AND(I10="*", OR(F9="*", G9="*",H9="*")),1,"") | M9: =IF(AND(E10="*",OR(F9="*",G9="*",H9="*",I9="*")),1,IF(AND(I9="*",OR(E10="*",F10="*",G10="*",H10="*")),1,"")) | N9: =IF(AND(F9="*",OR(F10="*",G10="*",H10="*")),1,IF(AND(G9="*",OR(F10="*",G10="*",H10="*")),1,IF(AND(H9="*",OR(F10="*",G10="*",H10="*")),1,""))) | O9: =IF(AND(E9="*",E10="*"),1,"") | V9: =IF(AND(Q9="*",OR(R10="*",S10="*",T10="*")), 1,"") | W9: =IF(AND(Q9="*",U10="*"),1,"") | X9: =IF(AND(U10="*", OR(R9="*", S9="*",T9="*")),1,"") | Y9: =IF(AND(Q10="*",OR(R9="*",S9="*",T9="*",U9="*")),1,IF(AND(U9="*",OR(Q10="*",R10="*",S10="*",T10="*")),1,"")) | Z9: =IF(AND(R9="*",OR(R10="*",S10="*",T10="*")),1,IF(AND(S9="*",OR(R10="*",S10="*",T10="*")),1,IF(AND(T9="*",OR(R10="*",S10="*",T10="*")),1,""))) | AA9: =IF(AND(Q9="*",Q10="*"),1,"") | AH9: =IF(AND(AC9="*",OR(AD10="*",AE10="*",AF10="*")), 1,"") | AI9: =IF(AND(AC9="*",AG10="*"),1,"") | AJ9: =IF(AND(AG10="*", OR(AD9="*", AE9="*",AF9="*")),1,"") | AK9: =IF(AND(AC10="*",OR(AD9="*",AE9="*",AF9="*",AG9="*")),1,IF(AND(AG9="*",OR(AC10="*",AD10="*",AE10="*",AF10="*")),1,"")) | AL9: =IF(AND(AD9="*",OR(AD10="*",AE10="*",AF10="*")),1,IF(AND(AE9="*",OR(AD10="*",AE10="*",AF10="*")),1,IF(AND(AF9="*",OR(AD10="*",AE10="*",AF10="*")),1,""))) | AM9: =IF(AND(AC9="*",AC10="*"),1,"") | AT9: =IF(AND(AO9="*",OR(AP10="*",AQ10="*",AR10="*")), 1,"") | AU9: =IF(AND(AO9="*",AS10="*"),1,"") | AV9: =IF(AND(AS10="*", OR(AP9="*", AQ9="*",AR9="*")),1,"") | AW9: =IF(AND(AO10="*",OR(AP9="*",AQ9="*",AR9="*",AS9="*")),1,IF(AND(AS9="*",OR(AO10="*",AP10="*",AQ10="*",AR10="*")),1,"")) | AX9: =IF(AND(AP9="*",OR(AP10="*",AQ10="*",AR10="*")),1,IF(AND(AQ9="*",OR(AP10="*",AQ10="*",AR10="*")),1,IF(AND(AR9="*",OR(AP10="*",AQ10="*",AR10="*")),1,""))) | AY9: =IF(AND(AO9="*",AO10="*"),1,"") | BF9: =IF(AND(BA9="*",OR(BB10="*",BC10="*",BD10="*")), 1,"") | BG9: =IF(AND(BA9="*",BE10="*"),1,"") | BH9: =IF(AND(BE10="*", OR(BB9="*", BC9="*",BD9="*")),1,"") | BI9: =IF(AND(BA10="*",OR(BB9="*",BC9="*",BD9="*",BE9="*")),1,IF(AND(BE9="*",OR(BA10="*",BB10="*",BC10="*",BD10="*")),1,"")) | BJ9: =IF(AND(BB9="*",OR(BB10="*",BC10="*",BD10="*")),1,IF(AND(BC9="*",OR(BB10="*",BC10="*",BD10="*")),1,IF(AND(BD9="*",OR(BB10="*",BC10="*",BD10="*")),1,""))) | BK9: =IF(AND(BA9="*",BA10="*"),1,"") | BS9: =IF(AND(BM9="*",OR(BN10="*",BO10="*",BP10="*")), 1,"") | BT9: =IF(AND(BM9="*",BQ10="*"),1,"") | BU9: =IF(AND(BQ10="*", OR(BN9="*", BO9="*",BP9="*")),1,"") | BV9: =IF(AND(BM10="*",OR(BN9="*",BO9="*",BP9="*",BQ9="*")),1,IF(AND(BQ9="*",OR(BM10="*",BN10="*",BO10="*",BP10="*")),1,"")) | BW9: =IF(AND(BN9="*",OR(BN10="*",BO10="*",BP10="*")),1,IF(AND(BO9="*",OR(BN10="*",BO10="*",BP10="*")),1,IF(AND(BP9="*",OR(BN10="*",BO10="*",BP10="*")),1,""))) | BX9: =IF(AND(BM9="*",BM10="*"),1,"") | CE9: =IF(AND(BZ9="*",OR(CA10="*",CB10="*",CC10="*")), 1,"") | CF9: =IF(AND(BZ9="*",CD10="*"),1,"") | CG9: =IF(AND(CD10="*", OR(CA9="*", CB9="*",CC9="*")),1,"") | CH9: =IF(AND(BZ10="*",OR(CA9="*",CB9="*",CC9="*",CD9="*")),1,IF(AND(CD9="*",OR(BZ10="*",CA10="*",CB10="*",CC10="*")),1,"")) | CI9: =IF(AND(CA9="*",OR(CA10="*",CB10="*",CC10="*")),1,IF(AND(CB9="*",OR(CA10="*",CB10="*",CC10="*")),1,IF(AND(CC9="*",OR(CA10="*",CB10="*",CC10="*")),1,""))) | CJ9: =IF(AND(BZ9="*",BZ10="*"),1,"") | CQ9: =IF(AND(CL9="*",OR(CM10="*",CN10="*",CO10="*")), 1,"") | CR9: =IF(AND(CL9="*",CP10="*"),1,"") | CS9: =IF(AND(CP10="*", OR(CM9="*", CN9="*",CO9="*")),1,"") | CT9: =IF(AND(CL10="*",OR(CM9="*",CN9="*",CO9="*",CP9="*")),1,IF(AND(CP9="*",OR(CL10="*",CM10="*",CN10="*",CO10="*")),1,"")) | CU9: =IF(AND(CM9="*",OR(CM10="*",CN10="*",CO10="*")),1,IF(AND(CN9="*",OR(CM10="*",CN10="*",CO10="*")),1,IF(AND(CO9="*",OR(CM10="*",CN10="*",CO10="*")),1,""))) | CV9: =IF(AND(CL9="*",CL10="*"),1,"") | DC9: =IF(AND(CX9="*",OR(CY10="*",CZ10="*",DA10="*")), 1,"") | DD9: =IF(AND(CX9="*",DB10="*"),1,"") | DE9: =IF(AND(DB10="*", OR(CY9="*", CZ9="*",DA9="*")),1,"") | DF9: =IF(AND(CX10="*",OR(CY9="*",CZ9="*",DA9="*",DB9="*")),1,IF(AND(DB9="*",OR(CX10="*",CY10="*",CZ10="*",DA10="*")),1,"")) | DG9: =IF(AND(CY9="*",OR(CY10="*",CZ10="*",DA10="*")),1,IF(AND(CZ9="*",OR(CY10="*",CZ10="*",DA10="*")),1,IF(AND(DA9="*",OR(CY10="*",CZ10="*",DA10="*")),1,""))) | DH9: =IF(AND(CX9="*",CX10="*"),1,"") | DO9: =IF(AND(DJ9="*",OR(DK10="*",DL10="*",DM10="*")), 1,"") | DP9: =IF(AND(DJ9="*",DN10="*"),1,"") | DQ9: =IF(AND(DN10="*", OR(DK9="*", DL9="*",DM9="*")),1,"") | DR9: =IF(AND(DJ10="*",OR(DK9="*",DL9="*",DM9="*",DN9="*")),1,IF(AND(DN9="*",OR(DJ10="*",DK10="*",DL10="*",DM10="*")),1,"")) | DS9: =IF(AND(DK9="*",OR(DK10="*",DL10="*",DM10="*")),1,IF(AND(DL9="*",OR(DK10="*",DL10="*",DM10="*")),1,IF(AND(DM9="*",OR(DK10="*",DL10="*",DM10="*")),1,""))) | DT9: =IF(AND(DJ9="*",DJ10="*"),1,"") | EA9: =IF(AND(DV9="*",OR(DW10="*",DX10="*",DY10="*")), 1,"") | EB9: =IF(AND(DV9="*",DZ10="*"),1,"") | EC9: =IF(AND(DZ10="*", OR(DW9="*", DX9="*",DY9="*")),1,"") | ED9: =IF(AND(DV10="*",OR(DW9="*",DX9="*",DY9="*",DZ9="*")),1,IF(AND(DZ9="*",OR(DV10="*",DW10="*",DX10="*",DY10="*")),1,"")) | EE9: =IF(AND(DW9="*",OR(DW10="*",DX10="*",DY10="*")),1,IF(AND(DX9="*",OR(DW10="*",DX10="*",DY10="*")),1,IF(AND(DY9="*",OR(DW10="*",DX10="*",DY10="*")),1,""))) | EF9: =IF(AND(DV9="*",DV10="*"),1,"") | EM9: =IF(AND(EH9="*",OR(EI10="*",EJ10="*",EK10="*")), 1,"") | EN9: =IF(AND(EH9="*",EL10="*"),1,"") | EO9: =IF(AND(EL10="*", OR(EI9="*", EJ9="*",EK9="*")),1,"") | EP9: =IF(AND(EH10="*",OR(EI9="*",EJ9="*",EK9="*",EL9="*")),1,IF(AND(EL9="*",OR(EH10="*",EI10="*",EJ10="*",EK10="*")),1,"")) | EQ9: =IF(AND(EI9="*",OR(EI10="*",EJ10="*",EK10="*")),1,IF(AND(EJ9="*",OR(EI10="*",EJ10="*",EK10="*")),1,IF(AND(EK9="*",OR(EI10="*",EJ10="*",EK10="*")),1,""))) | ER9: =IF(AND(EH9="*",EH10="*"),1,"") | EY9: =IF(AND(ET9="*",OR(EU10="*",EV10="*",EW10="*")), 1,"") | EZ9: =IF(AND(ET9="*",EX10="*"),1,"") | FA9: =IF(AND(EX10="*", OR(EU9="*", EV9="*",EW9="*")),1,"") | FB9: =IF(AND(ET10="*",OR(EU9="*",EV9="*",EW9="*",EX9="*")),1,IF(AND(EX9="*",OR(ET10="*",EU10="*",EV10="*",EW10="*")),1,"")) | FC9: =IF(AND(EU9="*",OR(EU10="*",EV10="*",EW10="*")),1,IF(AND(EV9="*",OR(EU10="*",EV10="*",EW10="*")),1,IF(AND(EW9="*",OR(EU10="*",EV10="*",EW10="*")),1,""))) | FD9: =IF(AND(ET9="*",ET10="*"),1,"") | FK9: =IF(AND(FF9="*",OR(FG10="*",FH10="*",FI10="*")), 1,"") | FL9: =IF(AND(FF9="*",FJ10="*"),1,"") | FM9: =IF(AND(FJ10="*", OR(FG9="*", FH9="*",FI9="*")),1,"") | FN9: =IF(AND(FF10="*",OR(FG9="*",FH9="*",FI9="*",FJ9="*")),1,IF(AND(FJ9="*",OR(FF10="*",FG10="*",FH10="*",FI10="*")),1,"")) | FO9: =IF(AND(FG9="*",OR(FG10="*",FH10="*",FI10="*")),1,IF(AND(FH9="*",OR(FG10="*",FH10="*",FI10="*")),1,IF(AND(FI9="*",OR(FG10="*",FH10="*",FI10="*")),1,""))) | FP9: =IF(AND(FF9="*",FF10="*"),1,"") | FW9: =IF(AND(FR9="*",OR(FS10="*",FT10="*",FU10="*")), 1,"") | FX9: =IF(AND(FR9="*",FV10="*"),1,"") | FY9: =IF(AND(FV10="*", OR(FS9="*", FT9="*",FU9="*")),1,"") | FZ9: =IF(AND(FR10="*",OR(FS9="*",FT9="*",FU9="*",FV9="*")),1,IF(AND(FV9="*",OR(FR10="*",FS10="*",FT10="*",FU10="*")),1,"")) | GA9: =IF(AND(FS9="*",OR(FS10="*",FT10="*",FU10="*")),1,IF(AND(FT9="*",OR(FS10="*",FT10="*",FU10="*")),1,IF(AND(FU9="*",OR(FS10="*",FT10="*",FU10="*")),1,""))) | GB9: =IF(AND(FR9="*",FR10="*"),1,"") | GJ9: =IF(AND(GD9="*",OR(GE10="*",GF10="*",GG10="*")), 1,"") | GK9: =IF(AND(GD9="*",GH10="*"),1,"") | GL9: =IF(AND(GH10="*", OR(GE9="*", GF9="*",GG9="*")),1,"") | GM9: =IF(AND(GD10="*",OR(GE9="*",GF9="*",GG9="*",GH9="*")),1,IF(AND(GH9="*",OR(GD10="*",GE10="*",GF10="*",GG10="*")),1,"")) | GN9: =IF(AND(GE9="*",OR(GE10="*",GF10="*",GG10="*")),1,IF(AND(GF9="*",OR(GE10="*",GF10="*",GG10="*")),1,IF(AND(GG9="*",OR(GE10="*",GF10="*",GG10="*")),1,""))) | GO9: =IF(AND(GD9="*",GD10="*"),1,"") | GV9: =IF(AND(GQ9="*",OR(GR10="*",GS10="*",GT10="*")), 1,"") | GW9: =IF(AND(GQ9="*",GU10="*"),1,"") | GX9: =IF(AND(GU10="*", OR(GR9="*", GS9="*",GT9="*")),1,"") | GY9: =IF(AND(GQ10="*",OR(GR9="*",GS9="*",GT9="*",GU9="*")),1,IF(AND(GU9="*",OR(GQ10="*",GR10="*",GS10="*",GT10="*")),1,"")) | GZ9: =IF(AND(GR9="*",OR(GR10="*",GS10="*",GT10="*")),1,IF(AND(GS9="*",OR(GR10="*",GS10="*",GT10="*")),1,IF(AND(GT9="*",OR(GR10="*",GS10="*",GT10="*")),1,""))) | HA9: =IF(AND(GQ9="*",GQ10="*"),1,"") | HH9: =IF(AND(HC9="*",OR(HD10="*",HE10="*",HF10="*")), 1,"") | HI9: =IF(AND(HC9="*",HG10="*"),1,"") | HJ9: =IF(AND(HG10="*", OR(HD9="*", HE9="*",HF9="*")),1,"") | HK9: =IF(AND(HC10="*",OR(HD9="*",HE9="*",HF9="*",HG9="*")),1,IF(AND(HG9="*",OR(HC10="*",HD10="*",HE10="*",HF10="*")),1,"")) | HL9: =IF(AND(HD9="*",OR(HD10="*",HE10="*",HF10="*")),1,IF(AND(HE9="*",OR(HD10="*",HE10="*",HF10="*")),1,IF(AND(HF9="*",OR(HD10="*",HE10="*",HF10="*")),1,""))) | HM9: =IF(AND(HC9="*",HC10="*"),1,"") | HT9: =IF(AND(HO9="*",OR(HP10="*",HQ10="*",HR10="*")), 1,"") | HU9: =IF(AND(HO9="*",HS10="*"),1,"") | HV9: =IF(AND(HS10="*", OR(HP9="*", HQ9="*",HR9="*")),1,"") | HW9: =IF(AND(HO10="*",OR(HP9="*",HQ9="*",HR9="*",HS9="*")),1,IF(AND(HS9="*",OR(HO10="*",HP10="*",HQ10="*",HR10="*")),1,"")) | HX9: =IF(AND(HP9="*",OR(HP10="*",HQ10="*",HR10="*")),1,IF(AND(HQ9="*",OR(HP10="*",HQ10="*",HR10="*")),1,IF(AND(HR9="*",OR(HP10="*",HQ10="*",HR10="*")),1,""))) | HY9: =IF(AND(HO9="*",HO10="*"),1,"") | IF9: =IF(AND(IA9="*",OR(IB10="*",IC10="*",ID10="*")), 1,"") | IG9: =IF(AND(IA9="*",IE10="*"),1,"") | IH9: =IF(AND(IE10="*", OR(IB9="*", IC9="*",ID9="*")),1,"") | II9: =IF(AND(IA10="*",OR(IB9="*",IC9="*",ID9="*",IE9="*")),1,IF(AND(IE9="*",OR(IA10="*",IB10="*",IC10="*",ID10="*")),1,"")) | IJ9: =IF(AND(IB9="*",OR(IB10="*",IC10="*",ID10="*")),1,IF(AND(IC9="*",OR(IB10="*",IC10="*",ID10="*")),1,IF(AND(ID9="*",OR(IB10="*",IC10="*",ID10="*")),1,""))) | IK9: =IF(AND(IA9="*",IA10="*"),1,"") | IL9: =COUNT(J9,V9,AH9,AT9,BF9,BS9,CE9,CQ9,DC9,DO9,EA9,EM9,EY9,FK9,FW9,GJ9,GV9,HH9,HT9,IF9) -> 0 | IM9: =COUNT(K9,W9,AI9,AU9,BG9,BT9,CF9,CR9,DD9,DP9,EB9,EN9,EZ9,FL9,FX9,GK9,GW9,HI9,HU9,IG9) -> 0 | IN9: =COUNT(L9,X9,AJ9,AV9,BH9,BU9,CG9,CS9,DE9,DQ9,EC9,EO9,FA9,FM9,FY9,GL9,GX9,HJ9,HV9,IH9) -> 0 | IO9: =COUNT(M9,Y9,AK9,AW9,BI9,BV9,CH9,CT9,DF9,DR9,ED9,EP9,FB9,FN9,FZ9,GM9,GY9,HK9,HW9,II9) -> 0 | IP9: =COUNT(N9,Z9,AL9,AX9,BJ9,BW9,CI9,CU9,DG9,DS9,EE9,EQ9,FC9,FO9,GA9,GN9,GZ9,HL9,HX9,IJ9) -> 0 | IQ9: =COUNT(O9,AA9,AM9,AY9,BK9,BX9,CJ9,CV9,DH9,DT9,EF9,ER9,FD9,FP9,GB9,GO9,HA9,HM9,HY9,IK9) -> 0
D10: 부정적 질문
B11: 5 | C11: =고객요구사항도출표!C9 -> 0 | D11: 긍정적 질문 | J11: =IF(AND(E11="*",OR(F12="*",G12="*",H12="*")), 1,"") | K11: =IF(AND(E11="*",I12="*"),1,"") | L11: =IF(AND(I12="*", OR(F11="*", G11="*",H11="*")),1,"") | M11: =IF(AND(E12="*",OR(F11="*",G11="*",H11="*",I11="*")),1,IF(AND(I11="*",OR(E12="*",F12="*",G12="*",H12="*")),1,"")) | N11: =IF(AND(F11="*",OR(F12="*",G12="*",H12="*")),1,IF(AND(G11="*",OR(F12="*",G12="*",H12="*")),1,IF(AND(H11="*",OR(F12="*",G12="*",H12="*")),1,""))) | O11: =IF(AND(E11="*",E12="*"),1,"") | V11: =IF(AND(Q11="*",OR(R12="*",S12="*",T12="*")), 1,"") | W11: =IF(AND(Q11="*",U12="*"),1,"") | X11: =IF(AND(U12="*", OR(R11="*", S11="*",T11="*")),1,"") | Y11: =IF(AND(Q12="*",OR(R11="*",S11="*",T11="*",U11="*")),1,IF(AND(U11="*",OR(Q12="*",R12="*",S12="*",T12="*")),1,"")) | Z11: =IF(AND(R11="*",OR(R12="*",S12="*",T12="*")),1,IF(AND(S11="*",OR(R12="*",S12="*",T12="*")),1,IF(AND(T11="*",OR(R12="*",S12="*",T12="*")),1,""))) | AA11: =IF(AND(Q11="*",Q12="*"),1,"") | AH11: =IF(AND(AC11="*",OR(AD12="*",AE12="*",AF12="*")), 1,"") | AI11: =IF(AND(AC11="*",AG12="*"),1,"") | AJ11: =IF(AND(AG12="*", OR(AD11="*", AE11="*",AF11="*")),1,"") | AK11: =IF(AND(AC12="*",OR(AD11="*",AE11="*",AF11="*",AG11="*")),1,IF(AND(AG11="*",OR(AC12="*",AD12="*",AE12="*",AF12="*")),1,"")) | AL11: =IF(AND(AD11="*",OR(AD12="*",AE12="*",AF12="*")),1,IF(AND(AE11="*",OR(AD12="*",AE12="*",AF12="*")),1,IF(AND(AF11="*",OR(AD12="*",AE12="*",AF12="*")),1,""))) | AM11: =IF(AND(AC11="*",AC12="*"),1,"") | AT11: =IF(AND(AO11="*",OR(AP12="*",AQ12="*",AR12="*")), 1,"") | AU11: =IF(AND(AO11="*",AS12="*"),1,"") | AV11: =IF(AND(AS12="*", OR(AP11="*", AQ11="*",AR11="*")),1,"") | AW11: =IF(AND(AO12="*",OR(AP11="*",AQ11="*",AR11="*",AS11="*")),1,IF(AND(AS11="*",OR(AO12="*",AP12="*",AQ12="*",AR12="*")),1,"")) | AX11: =IF(AND(AP11="*",OR(AP12="*",AQ12="*",AR12="*")),1,IF(AND(AQ11="*",OR(AP12="*",AQ12="*",AR12="*")),1,IF(AND(AR11="*",OR(AP12="*",AQ12="*",AR12="*")),1,""))) | AY11: =IF(AND(AO11="*",AO12="*"),1,"") | BF11: =IF(AND(BA11="*",OR(BB12="*",BC12="*",BD12="*")), 1,"") | BG11: =IF(AND(BA11="*",BE12="*"),1,"") | BH11: =IF(AND(BE12="*", OR(BB11="*", BC11="*",BD11="*")),1,"") | BI11: =IF(AND(BA12="*",OR(BB11="*",BC11="*",BD11="*",BE11="*")),1,IF(AND(BE11="*",OR(BA12="*",BB12="*",BC12="*",BD12="*")),1,"")) | BJ11: =IF(AND(BB11="*",OR(BB12="*",BC12="*",BD12="*")),1,IF(AND(BC11="*",OR(BB12="*",BC12="*",BD12="*")),1,IF(AND(BD11="*",OR(BB12="*",BC12="*",BD12="*")),1,""))) | BK11: =IF(AND(BA11="*",BA12="*"),1,"") | BS11: =IF(AND(BM11="*",OR(BN12="*",BO12="*",BP12="*")), 1,"") | BT11: =IF(AND(BM11="*",BQ12="*"),1,"") | BU11: =IF(AND(BQ12="*", OR(BN11="*", BO11="*",BP11="*")),1,"") | BV11: =IF(AND(BM12="*",OR(BN11="*",BO11="*",BP11="*",BQ11="*")),1,IF(AND(BQ11="*",OR(BM12="*",BN12="*",BO12="*",BP12="*")),1,"")) | BW11: =IF(AND(BN11="*",OR(BN12="*",BO12="*",BP12="*")),1,IF(AND(BO11="*",OR(BN12="*",BO12="*",BP12="*")),1,IF(AND(BP11="*",OR(BN12="*",BO12="*",BP12="*")),1,""))) | BX11: =IF(AND(BM11="*",BM12="*"),1,"") | CE11: =IF(AND(BZ11="*",OR(CA12="*",CB12="*",CC12="*")), 1,"") | CF11: =IF(AND(BZ11="*",CD12="*"),1,"") | CG11: =IF(AND(CD12="*", OR(CA11="*", CB11="*",CC11="*")),1,"") | CH11: =IF(AND(BZ12="*",OR(CA11="*",CB11="*",CC11="*",CD11="*")),1,IF(AND(CD11="*",OR(BZ12="*",CA12="*",CB12="*",CC12="*")),1,"")) | CI11: =IF(AND(CA11="*",OR(CA12="*",CB12="*",CC12="*")),1,IF(AND(CB11="*",OR(CA12="*",CB12="*",CC12="*")),1,IF(AND(CC11="*",OR(CA12="*",CB12="*",CC12="*")),1,""))) | CJ11: =IF(AND(BZ11="*",BZ12="*"),1,"") | CQ11: =IF(AND(CL11="*",OR(CM12="*",CN12="*",CO12="*")), 1,"") | CR11: =IF(AND(CL11="*",CP12="*"),1,"") | CS11: =IF(AND(CP12="*", OR(CM11="*", CN11="*",CO11="*")),1,"") | CT11: =IF(AND(CL12="*",OR(CM11="*",CN11="*",CO11="*",CP11="*")),1,IF(AND(CP11="*",OR(CL12="*",CM12="*",CN12="*",CO12="*")),1,"")) | CU11: =IF(AND(CM11="*",OR(CM12="*",CN12="*",CO12="*")),1,IF(AND(CN11="*",OR(CM12="*",CN12="*",CO12="*")),1,IF(AND(CO11="*",OR(CM12="*",CN12="*",CO12="*")),1,""))) | CV11: =IF(AND(CL11="*",CL12="*"),1,"") | DC11: =IF(AND(CX11="*",OR(CY12="*",CZ12="*",DA12="*")), 1,"") | DD11: =IF(AND(CX11="*",DB12="*"),1,"") | DE11: =IF(AND(DB12="*", OR(CY11="*", CZ11="*",DA11="*")),1,"") | DF11: =IF(AND(CX12="*",OR(CY11="*",CZ11="*",DA11="*",DB11="*")),1,IF(AND(DB11="*",OR(CX12="*",CY12="*",CZ12="*",DA12="*")),1,"")) | DG11: =IF(AND(CY11="*",OR(CY12="*",CZ12="*",DA12="*")),1,IF(AND(CZ11="*",OR(CY12="*",CZ12="*",DA12="*")),1,IF(AND(DA11="*",OR(CY12="*",CZ12="*",DA12="*")),1,""))) | DH11: =IF(AND(CX11="*",CX12="*"),1,"") | DO11: =IF(AND(DJ11="*",OR(DK12="*",DL12="*",DM12="*")), 1,"") | DP11: =IF(AND(DJ11="*",DN12="*"),1,"") | DQ11: =IF(AND(DN12="*", OR(DK11="*", DL11="*",DM11="*")),1,"") | DR11: =IF(AND(DJ12="*",OR(DK11="*",DL11="*",DM11="*",DN11="*")),1,IF(AND(DN11="*",OR(DJ12="*",DK12="*",DL12="*",DM12="*")),1,"")) | DS11: =IF(AND(DK11="*",OR(DK12="*",DL12="*",DM12="*")),1,IF(AND(DL11="*",OR(DK12="*",DL12="*",DM12="*")),1,IF(AND(DM11="*",OR(DK12="*",DL12="*",DM12="*")),1,""))) | DT11: =IF(AND(DJ11="*",DJ12="*"),1,"") | EA11: =IF(AND(DV11="*",OR(DW12="*",DX12="*",DY12="*")), 1,"") | EB11: =IF(AND(DV11="*",DZ12="*"),1,"") | EC11: =IF(AND(DZ12="*", OR(DW11="*", DX11="*",DY11="*")),1,"") | ED11: =IF(AND(DV12="*",OR(DW11="*",DX11="*",DY11="*",DZ11="*")),1,IF(AND(DZ11="*",OR(DV12="*",DW12="*",DX12="*",DY12="*")),1,"")) | EE11: =IF(AND(DW11="*",OR(DW12="*",DX12="*",DY12="*")),1,IF(AND(DX11="*",OR(DW12="*",DX12="*",DY12="*")),1,IF(AND(DY11="*",OR(DW12="*",DX12="*",DY12="*")),1,""))) | EF11: =IF(AND(DV11="*",DV12="*"),1,"") | EM11: =IF(AND(EH11="*",OR(EI12="*",EJ12="*",EK12="*")), 1,"") | EN11: =IF(AND(EH11="*",EL12="*"),1,"") | EO11: =IF(AND(EL12="*", OR(EI11="*", EJ11="*",EK11="*")),1,"") | EP11: =IF(AND(EH12="*",OR(EI11="*",EJ11="*",EK11="*",EL11="*")),1,IF(AND(EL11="*",OR(EH12="*",EI12="*",EJ12="*",EK12="*")),1,"")) | EQ11: =IF(AND(EI11="*",OR(EI12="*",EJ12="*",EK12="*")),1,IF(AND(EJ11="*",OR(EI12="*",EJ12="*",EK12="*")),1,IF(AND(EK11="*",OR(EI12="*",EJ12="*",EK12="*")),1,""))) | ER11: =IF(AND(EH11="*",EH12="*"),1,"") | EY11: =IF(AND(ET11="*",OR(EU12="*",EV12="*",EW12="*")), 1,"") | EZ11: =IF(AND(ET11="*",EX12="*"),1,"") | FA11: =IF(AND(EX12="*", OR(EU11="*", EV11="*",EW11="*")),1,"") | FB11: =IF(AND(ET12="*",OR(EU11="*",EV11="*",EW11="*",EX11="*")),1,IF(AND(EX11="*",OR(ET12="*",EU12="*",EV12="*",EW12="*")),1,"")) | FC11: =IF(AND(EU11="*",OR(EU12="*",EV12="*",EW12="*")),1,IF(AND(EV11="*",OR(EU12="*",EV12="*",EW12="*")),1,IF(AND(EW11="*",OR(EU12="*",EV12="*",EW12="*")),1,""))) | FD11: =IF(AND(ET11="*",ET12="*"),1,"") | FK11: =IF(AND(FF11="*",OR(FG12="*",FH12="*",FI12="*")), 1,"") | FL11: =IF(AND(FF11="*",FJ12="*"),1,"") | FM11: =IF(AND(FJ12="*", OR(FG11="*", FH11="*",FI11="*")),1,"") | FN11: =IF(AND(FF12="*",OR(FG11="*",FH11="*",FI11="*",FJ11="*")),1,IF(AND(FJ11="*",OR(FF12="*",FG12="*",FH12="*",FI12="*")),1,"")) | FO11: =IF(AND(FG11="*",OR(FG12="*",FH12="*",FI12="*")),1,IF(AND(FH11="*",OR(FG12="*",FH12="*",FI12="*")),1,IF(AND(FI11="*",OR(FG12="*",FH12="*",FI12="*")),1,""))) | FP11: =IF(AND(FF11="*",FF12="*"),1,"") | FW11: =IF(AND(FR11="*",OR(FS12="*",FT12="*",FU12="*")), 1,"") | FX11: =IF(AND(FR11="*",FV12="*"),1,"") | FY11: =IF(AND(FV12="*", OR(FS11="*", FT11="*",FU11="*")),1,"") | FZ11: =IF(AND(FR12="*",OR(FS11="*",FT11="*",FU11="*",FV11="*")),1,IF(AND(FV11="*",OR(FR12="*",FS12="*",FT12="*",FU12="*")),1,"")) | GA11: =IF(AND(FS11="*",OR(FS12="*",FT12="*",FU12="*")),1,IF(AND(FT11="*",OR(FS12="*",FT12="*",FU12="*")),1,IF(AND(FU11="*",OR(FS12="*",FT12="*",FU12="*")),1,""))) | GB11: =IF(AND(FR11="*",FR12="*"),1,"") | GJ11: =IF(AND(GD11="*",OR(GE12="*",GF12="*",GG12="*")), 1,"") | GK11: =IF(AND(GD11="*",GH12="*"),1,"") | GL11: =IF(AND(GH12="*", OR(GE11="*", GF11="*",GG11="*")),1,"") | GM11: =IF(AND(GD12="*",OR(GE11="*",GF11="*",GG11="*",GH11="*")),1,IF(AND(GH11="*",OR(GD12="*",GE12="*",GF12="*",GG12="*")),1,"")) | GN11: =IF(AND(GE11="*",OR(GE12="*",GF12="*",GG12="*")),1,IF(AND(GF11="*",OR(GE12="*",GF12="*",GG12="*")),1,IF(AND(GG11="*",OR(GE12="*",GF12="*",GG12="*")),1,""))) | GO11: =IF(AND(GD11="*",GD12="*"),1,"") | GV11: =IF(AND(GQ11="*",OR(GR12="*",GS12="*",GT12="*")), 1,"") | GW11: =IF(AND(GQ11="*",GU12="*"),1,"") | GX11: =IF(AND(GU12="*", OR(GR11="*", GS11="*",GT11="*")),1,"") | GY11: =IF(AND(GQ12="*",OR(GR11="*",GS11="*",GT11="*",GU11="*")),1,IF(AND(GU11="*",OR(GQ12="*",GR12="*",GS12="*",GT12="*")),1,"")) | GZ11: =IF(AND(GR11="*",OR(GR12="*",GS12="*",GT12="*")),1,IF(AND(GS11="*",OR(GR12="*",GS12="*",GT12="*")),1,IF(AND(GT11="*",OR(GR12="*",GS12="*",GT12="*")),1,""))) | HA11: =IF(AND(GQ11="*",GQ12="*"),1,"") | HH11: =IF(AND(HC11="*",OR(HD12="*",HE12="*",HF12="*")), 1,"") | HI11: =IF(AND(HC11="*",HG12="*"),1,"") | HJ11: =IF(AND(HG12="*", OR(HD11="*", HE11="*",HF11="*")),1,"") | HK11: =IF(AND(HC12="*",OR(HD11="*",HE11="*",HF11="*",HG11="*")),1,IF(AND(HG11="*",OR(HC12="*",HD12="*",HE12="*",HF12="*")),1,"")) | HL11: =IF(AND(HD11="*",OR(HD12="*",HE12="*",HF12="*")),1,IF(AND(HE11="*",OR(HD12="*",HE12="*",HF12="*")),1,IF(AND(HF11="*",OR(HD12="*",HE12="*",HF12="*")),1,""))) | HM11: =IF(AND(HC11="*",HC12="*"),1,"") | HT11: =IF(AND(HO11="*",OR(HP12="*",HQ12="*",HR12="*")), 1,"") | HU11: =IF(AND(HO11="*",HS12="*"),1,"") | HV11: =IF(AND(HS12="*", OR(HP11="*", HQ11="*",HR11="*")),1,"") | HW11: =IF(AND(HO12="*",OR(HP11="*",HQ11="*",HR11="*",HS11="*")),1,IF(AND(HS11="*",OR(HO12="*",HP12="*",HQ12="*",HR12="*")),1,"")) | HX11: =IF(AND(HP11="*",OR(HP12="*",HQ12="*",HR12="*")),1,IF(AND(HQ11="*",OR(HP12="*",HQ12="*",HR12="*")),1,IF(AND(HR11="*",OR(HP12="*",HQ12="*",HR12="*")),1,""))) | HY11: =IF(AND(HO11="*",HO12="*"),1,"") | IF11: =IF(AND(IA11="*",OR(IB12="*",IC12="*",ID12="*")), 1,"") | IG11: =IF(AND(IA11="*",IE12="*"),1,"") | IH11: =IF(AND(IE12="*", OR(IB11="*", IC11="*",ID11="*")),1,"") | II11: =IF(AND(IA12="*",OR(IB11="*",IC11="*",ID11="*",IE11="*")),1,IF(AND(IE11="*",OR(IA12="*",IB12="*",IC12="*",ID12="*")),1,"")) | IJ11: =IF(AND(IB11="*",OR(IB12="*",IC12="*",ID12="*")),1,IF(AND(IC11="*",OR(IB12="*",IC12="*",ID12="*")),1,IF(AND(ID11="*",OR(IB12="*",IC12="*",ID12="*")),1,""))) | IK11: =IF(AND(IA11="*",IA12="*"),1,"") | IL11: =COUNT(J11,V11,AH11,AT11,BF11,BS11,CE11,CQ11,DC11,DO11,EA11,EM11,EY11,FK11,FW11,GJ11,GV11,HH11,HT11,IF11) -> 0 | IM11: =COUNT(K11,W11,AI11,AU11,BG11,BT11,CF11,CR11,DD11,DP11,EB11,EN11,EZ11,FL11,FX11,GK11,GW11,HI11,HU11,IG11) -> 0 | IN11: =COUNT(L11,X11,AJ11,AV11,BH11,BU11,CG11,CS11,DE11,DQ11,EC11,EO11,FA11,FM11,FY11,GL11,GX11,HJ11,HV11,IH11) -> 0 | IO11: =COUNT(M11,Y11,AK11,AW11,BI11,BV11,CH11,CT11,DF11,DR11,ED11,EP11,FB11,FN11,FZ11,GM11,GY11,HK11,HW11,II11) -> 0 | IP11: =COUNT(N11,Z11,AL11,AX11,BJ11,BW11,CI11,CU11,DG11,DS11,EE11,EQ11,FC11,FO11,GA11,GN11,GZ11,HL11,HX11,IJ11) -> 0 | IQ11: =COUNT(O11,AA11,AM11,AY11,BK11,BX11,CJ11,CV11,DH11,DT11,EF11,ER11,FD11,FP11,GB11,GO11,HA11,HM11,HY11,IK11) -> 0
D12: 부정적 질문
